Workbook

Sheet 6-1-26
A1: KOPERASI SERBA USAHA "CAHAYA DHAMMA PHALA"
A2: Badan Hukum No. 2/BH/XIV.1/II/2016 Tanggal 5 Februari 2016
A3: Dukuh Windusari, Desa Sokaraja, Kec. Pagentan, Kab. Banjarnegara 53455
A5: BUKU ANGSURAN PINJAMAN ANGGOTA
A6: Per 6 Januari 2025
A7: NO. | B7: NAMA | C7: TGL | E7: ANGSURAN PINJAMAN | I7: SISA | J7: SWK
E8: KE | F8: POKOK | G8: JASA | H8: JUMLAH
A9: 1 | B9: Suryadi | C9: 4-4-17 | D9: 5500000 | F9: 0 | G9: =SUM(E9:F9) -> 0 | H9: =SUM(F9:G9) -> 0 | I9: =D9-F9 -> 5500000 | J9: =1/10*G9 -> 0
A10: 2 | B10: Waginah | C10: 16-5-17 | D10: 1910000 | H10: =SUM(F10:G10) -> 0 | I10: =D10-F10 -> 1910000 | J10: =1/10*G10 -> 0
A11: 3 | B11: Tarmono | C11: 18-8-20 | D11: 1750000 | H11: =SUM(F11:G11) -> 0 | I11: =D11-F11 -> 1750000 | J11: =1/10*G11 -> 0
A12: 4 | B12: Juliyah | C12: 2-2-21 | D12: 13750000 | H12: =SUM(F12:G12) -> 0 | I12: =D12-F12 -> 13750000 | J12: =1/10*G12 -> 0
A13: 5 | B13: Purwadi | C13: 14-03-21 | D13: 19950000 | H13: =SUM(F13:G13) -> 0 | I13: =D13-F13 -> 19950000 | J13: =1/10*G13 -> 0
A14: 6 | B14: Waluyo Ragil | C14: 27-04-21 | D14: 100000 | H14: =SUM(F14:G14) -> 0 | I14: =D14-F14 -> 100000 | J14: =1/10*G14 -> 0
A15: 7 | B15: Sapdono | C15: 24-8-23 | D15: 10500000 | H15: =SUM(F15:G15) -> 0 | I15: =D15-F15 -> 10500000 | J15: =1/10*G15 -> 0
A16: 8 | B16: Sudarma Widya | C16: 28-09-21 | D16: 15310000 | H16: =SUM(F16:G16) -> 0 | I16: =D16-F16 -> 15310000 | J16: =1/10*G16 -> 0
A17: 9 | B17: Rahmadi | C17: 15-2-22 | D17: 6500000 | H17: =SUM(F17:G17) -> 0 | I17: =D17-F17 -> 6500000 | J17: =1/10*G17 -> 0
A18: 10 | B18: Ratmi | C18: 8-3-22 | D18: 13195000 | H18: =SUM(F18:G18) -> 0 | I18: =D18-F18 -> 13195000 | J18: =1/10*G18 -> 0
A19: 14 | B19: Cipret | C19: 21-6-22 | D19: 4250000 | E19: 4 | F19: 250000 | G19: 100000 | H19: =SUM(F19:G19) -> 350000 | I19: =D19-F19 -> 4000000 | J19: =1/10*G19 -> 10000
A20: 18 | B20: Ika Kurniasih | C20: 03-1-22 | D20: 42000000 | H20: =SUM(F20:G20) -> 0 | I20: =D20-F20 -> 42000000 | J20: =1/10*G20 -> 0
A21: 19 | B21: Kamto | C21: 28-2-23 | D21: 12680000 | H21: =SUM(F21:G21) -> 0 | I21: =D21-F21 -> 12680000 | J21: =1/10*G21 -> 0
A22: 22 | B22: Handi Cahyono | C22: 04-04-23 | D22: 9380000 | E22: 9 | F22: 9380000 | G22: 2450000 | H22: =SUM(F22:G22) -> 11830000 | I22: =D22-F22 -> 0 | J22: =1/10*G22 -> 245000
A23: 23 | B23: Hartati | C23: 04-04-23 | D23: 1500000 | H23: =SUM(F23:G23) -> 0 | I23: =D23-F23 -> 1500000 | J23: =1/10*G23 -> 0
A24: 24 | B24: Sartiyah | C24: 04-04-23 | D24: 600000 | H24: =SUM(F24:G24) -> 0 | I24: =D24-F24 -> 600000 | J24: =1/10*G24 -> 0
A25: 25 | B25: Dwi Vijjayanti | C25: 11-04-23 | D25: 22200000 | H25: =SUM(F25:G25) -> 0 | I25: =D25-F25 -> 22200000 | J25: =1/10*G25 -> 0
A26: 26 | B26: Marsinem | C26: 2-5-23 | D26: 4800000 | E26: 7 | F26: 1000000 | G26: 200000 | H26: =SUM(F26:G26) -> 1200000 | I26: =D26-F26 -> 3800000 | J26: =1/10*G26 -> 20000
A27: 29 | B27: Suharjanto | C27: 11/7/23 | D27: 1030000 | H27: =SUM(F27:G27) -> 0 | I27: =D27-F27 -> 1030000 | J27: =1/10*G27 -> 0
A28: 30 | B28: Saliyah | C28: 18/7/23 | D28: 1500000 | H28: =SUM(F28:G28) -> 0 | I28: =D28-F28 -> 1500000 | J28: =1/10*G28 -> 0
A29: 31 | B29: Suminah | C29: 26-9-23 | D29: 14000000 | E29: 4 | F29: 14000000 | G29: 3000000 | H29: =SUM(F29:G29) -> 17000000 | I29: =D29-F29 -> 0 | J29: =1/10*G29 -> 300000
A30: 33 | B30: Leni | C30: 10-10-23 | D30: 2750000 | H30: =SUM(F30:G30) -> 0 | I30: =D30-F30 -> 2750000 | J30: =1/10*G30 -> 0
A31: 34 | B31: Kasmi Purwadi | C31: 24-10-23 | D31: 1500000 | H31: =SUM(F31:G31) -> 0 | I31: =D31-F31 -> 1500000 | J31: =1/10*G31 -> 0
A32: 35 | B32: Gini Wanto | C32: 24-10-23 | D32: 12000000 | H32: =SUM(F32:G32) -> 0 | I32: =D32-F32 -> 12000000 | J32: =1/10*G32 -> 0
A33: 41 | B33: Kami | C33: 9/1/24 | D33: 750000 | H33: =SUM(F33:G33) -> 0 | I33: =D33-F33 -> 750000 | J33: =1/10*G33 -> 0
A34: 43 | B34: Wahyuni | C34: 30/1/24 | D34: 2800000 | H34: =SUM(F34:G34) -> 0 | I34: =D34-F34 -> 2800000 | J34: =1/10*G34 -> 0
A35: 44 | B35: Karsih | C35: 30/1/24 | D35: 3500000 | H35: =SUM(F35:G35) -> 0 | I35: =D35-F35 -> 3500000 | J35: =1/10*G35 -> 0
A36: 47 | B36: Painten Darwito | C36: 16/2/24 | D36: 12000000 | H36: =SUM(F36:G36) -> 0 | I36: =D36-F36 -> 12000000 | J36: =1/10*G36 -> 0
A37: 49 | B37: Karni | C37: 2/4/24 | D37: 1250000 | H37: =SUM(F37:G37) -> 0 | I37: =D37-F37 -> 1250000 | J37: =1/10*G37 -> 0
A38: 52 | B38: Siyo Dwiroso | C38: 16/4/24 | D38: 5800000 | H38: =SUM(F38:G38) -> 0 | I38: =D38-F38 -> 5800000 | J38: =1/10*G38 -> 0
A39: 60 | B39: Purwati | C39: 4/6/24 | D39: 14320000 | H39: =SUM(F39:G39) -> 0 | I39: =D39-F39 -> 14320000 | J39: =1/10*G39 -> 0
A40: 62 | B40: Tarsini | C40: 02/07/24 | D40: 400000 | H40: =SUM(F40:G40) -> 0 | I40: =D40-F40 -> 400000 | J40: =1/10*G40 -> 0
A41: 64 | B41: Santosa | C41: 09/07/24 | D41: 2100000 | H41: =SUM(F41:G41) -> 0 | I41: =D41-F41 -> 2100000 | J41: =1/10*G41 -> 0
...

Sheet 13-1-26
A1: KOPERASI SERBA USAHA "CAHAYA DHAMMA PHALA"
A2: Badan Hukum No. 2/BH/XIV.1/II/2016 Tanggal 5 Februari 2016
A3: Dukuh Windusari, Desa Sokaraja, Kec. Pagentan, Kab. Banjarnegara 53455
A5: BUKU ANGSURAN PINJAMAN ANGGOTA
A6: Per 13 Januari 2025
A7: NO. | B7: NAMA | C7: TGL | E7: ANGSURAN PINJAMAN | I7: SISA | J7: SWK
E8: KE | F8: POKOK | G8: JASA | H8: JUMLAH
A9: 1 | B9: Suryadi | C9: 4-4-17 | D9: ='6-1-26'!I9 -> 5500000 | F9: 0 | G9: =SUM(E9:F9) -> 0 | H9: =SUM(F9:G9) -> 0 | I9: =D9-F9 -> 5500000 | J9: =1/10*G9 -> 0
A10: 2 | B10: Waginah | C10: 16-5-17 | D10: ='6-1-26'!I10 -> 1910000 | H10: =SUM(F10:G10) -> 0 | I10: =D10-F10 -> 1910000 | J10: =1/10*G10 -> 0
A11: 3 | B11: Tarmono | C11: 18-8-20 | D11: ='6-1-26'!I11 -> 1750000 | H11: =SUM(F11:G11) -> 0 | I11: =D11-F11 -> 1750000 | J11: =1/10*G11 -> 0
A12: 4 | B12: Juliyah | C12: 2-2-21 | D12: ='6-1-26'!I12 -> 13750000 | H12: =SUM(F12:G12) -> 0 | I12: =D12-F12 -> 13750000 | J12: =1/10*G12 -> 0
A13: 5 | B13: Purwadi | C13: 14-03-21 | D13: ='6-1-26'!I13 -> 19950000 | H13: =SUM(F13:G13) -> 0 | I13: =D13-F13 -> 19950000 | J13: =1/10*G13 -> 0
A14: 6 | B14: Waluyo Ragil | C14: 27-04-21 | D14: ='6-1-26'!I14 -> 100000 | H14: =SUM(F14:G14) -> 0 | I14: =D14-F14 -> 100000 | J14: =1/10*G14 -> 0
A15: 7 | B15: Sapdono | C15: 24-8-23 | D15: ='6-1-26'!I15 -> 10500000 | H15: =SUM(F15:G15) -> 0 | I15: =D15-F15 -> 10500000 | J15: =1/10*G15 -> 0
A16: 8 | B16: Sudarma Widya | C16: 28-09-21 | D16: ='6-1-26'!I16 -> 15310000 | H16: =SUM(F16:G16) -> 0 | I16: =D16-F16 -> 15310000 | J16: =1/10*G16 -> 0
A17: 9 | B17: Rahmadi | C17: 15-2-22 | D17: ='6-1-26'!I17 -> 6500000 | H17: =SUM(F17:G17) -> 0 | I17: =D17-F17 -> 6500000 | J17: =1/10*G17 -> 0
A18: 10 | B18: Ratmi | C18: 8-3-22 | D18: ='6-1-26'!I18 -> 13195000 | H18: =SUM(F18:G18) -> 0 | I18: =D18-F18 -> 13195000 | J18: =1/10*G18 -> 0
A19: 14 | B19: Cipret | C19: 21-6-22 | D19: ='6-1-26'!I19 -> 4000000 | H19: =SUM(F19:G19) -> 0 | I19: =D19-F19 -> 4000000 | J19: =1/10*G19 -> 0
A20: 18 | B20: Ika Kurniasih | C20: 03-1-22 | D20: ='6-1-26'!I20 -> 42000000 | H20: =SUM(F20:G20) -> 0 | I20: =D20-F20 -> 42000000 | J20: =1/10*G20 -> 0
A21: 19 | B21: Kamto | C21: 28-2-23 | D21: ='6-1-26'!I21 -> 12680000 | H21: =SUM(F21:G21) -> 0 | I21: =D21-F21 -> 12680000 | J21: =1/10*G21 -> 0
... A27: 29 | B27: Suharjanto | C27: 11/7/23 | D27: ='6-1-26'!I27 -> 1030000 | H27: =SUM(F27:G27) -> 0 | I27: =D27-F27 -> 1030000 | J27: =1/10*G27 -> 0
A28: 30 | B28: Saliyah | C28: 18/7/23 | D28: ='6-1-26'!I28 -> 1500000 | E28: 14 | F28: 1500000 | G28: 500000 | H28: =SUM(F28:G28) -> 2000000 | I28: =D28-F28 -> 0 | J28: =1/10*G28 -> 50000
A29: 31 | B29: Suminah | C29: 26-9-23 | D29: ='6-1-26'!I29 -> 0 | H29: =SUM(F29:G29) -> 0 | I29: =D29-F29 -> 0 | J29: =1/10*G29 -> 0
A30: 33 | B30: Leni | C30: 10-10-23 | D30: ='6-1-26'!I30 -> 2750000 | H30: =SUM(F30:G30) -> 0 | I30: =D30-F30 -> 2750000 | J30: =1/10*G30 -> 0
A31: 34 | B31: Kasmi Purwadi | C31: 24-10-23 | D31: ='6-1-26'!I31 -> 1500000 | E31: 15 | F31: 250000 | G31: 100000 | H31: =SUM(F31:G31) -> 350000 | I31: =D31-F31 -> 1250000 | J31: =1/10*G31 -> 10000
A32: 35 | B32: Gini Wanto | C32: 24-10-23 | D32: ='6-1-26'!I32 -> 12000000 | H32: =SUM(F32:G32) -> 0 | I32: =D32-F32 -> 12000000 | J32: =1/10*G32 -> 0
A33: 41 | B33: Kami | C33: 9/1/24 | D33: ='6-1-26'!I33 -> 750000 | H33: =SUM(F33:G33) -> 0 | I33: =D33-F33 -> 750000 | J33: =1/10*G33 -> 0
A34: 43 | B34: Wahyuni | C34: 30/1/24 | D34: ='6-1-26'!I34 -> 2800000 | H34: =SUM(F34:G34) -> 0 | I34: =D34-F34 -> 2800000 | J34: =1/10*G34 -> 0
A35: 44 | B35: Karsih | C35: 30/1/24 | D35: ='6-1-26'!I35 -> 3500000 | H35: =SUM(F35:G35) -> 0 | I35: =D35-F35 -> 3500000 | J35: =1/10*G35 -> 0
A36: 47 | B36: Painten Darwito | C36: 16/2/24 | D36: ='6-1-26'!I36 -> 12000000 | H36: =SUM(F36:G36) -> 0 | I36: =D36-F36 -> 12000000 | J36: =1/10*G36 -> 0
A37: 49 | B37: Karni | C37: 2/4/24 | D37: ='6-1-26'!I37 -> 1250000 | H37: =SUM(F37:G37) -> 0 | I37: =D37-F37 -> 1250000 | J37: =1/10*G37 -> 0
A38: 52 | B38: Siyo Dwiroso | C38: 16/4/24 | D38: ='6-1-26'!I38 -> 5800000 | H38: =SUM(F38:G38) -> 0 | I38: =D38-F38 -> 5800000 | J38: =1/10*G38 -> 0
A39: 60 | B39: Purwati | C39: 4/6/24 | D39: ='6-1-26'!I39 -> 14320000 | H39: =SUM(F39:G39) -> 0 | I39: =D39-F39 -> 14320000 | J39: =1/10*G39 -> 0
A40: 62 | B40: Tarsini | C40: 02/07/24 | D40: ='6-1-26'!I40 -> 400000 | H40: =SUM(F40:G40) -> 0 | I40: =D40-F40 -> 400000 | J40: =1/10*G40 -> 0
A41: 64 | B41: Santosa | C41: 09/07/24 | D41: ='6-1-26'!I41 -> 2100000 | E41: 12 | F41: 300000 | G41: 120000 | H41: =SUM(F41:G41) -> 420000 | I41: =D41-F41 -> 1800000 | J41: =1/10*G41 -> 12000
A42: 65 | B42: Priyono | C42: 16/07/24 | D42: ='6-1-26'!I42 -> 1500000 | E42: 11 | F42: 300000 | G42: 120000 | H42: =SUM(F42:G42) -> 420000 | I42: =D42-F42 -> 1200000 | J42: =1/10*G42 -> 12000
A43: 69 | B43: Karyono | C43: 30/07/24 | D43: ='6-1-26'!I43 -> 6000000 | H43: =SUM(F43:G43) -> 0 | I43: =D43-F43 -> 6000000 | J43: =1/10*G43 -> 0
A44: 70 | B44: Dwiyanto | C44: 06/08/24 | D44: ='6-1-26'!I44 -> 11000000 | E44: 2 | F44: 680000 | G44: 320000 | H44: =SUM(F44:G44) -> 1000000 | I44: =D44-F44 -> 10320000 | J44: =1/10*G44 -> 32000
A45: 71 | B45: Utami | C45: 20/08/24 | D45: ='6-1-26'!I45 -> 11250000 | H45: =SUM(F45:G45) -> 0 | I45: =D45-F45 -> 11250000 | J45: =1/10*G45 -> 0
A46: 73 | B46: Karjono | C46: 10/09/24 | D46: ='6-1-26'!I46 -> 750000 | E46: 16 | F46: 150000 | G46: 60000 | H46: =SUM(F46:G46) -> 210000 | I46: =D46-F46 -> 600000 | J46: =1/10*G46 -> 6000
...

Sheet 20-1-26
A1: KOPERASI SERBA USAHA "CAHAYA DHAMMA PHALA"
A2: Badan Hukum No. 2/BH/XIV.1/II/2016 Tanggal 5 Februari 2016
A3: Dukuh Windusari, Desa Sokaraja, Kec. Pagentan, Kab. Banjarnegara 53455
A5: BUKU ANGSURAN PINJAMAN ANGGOTA
A6: Per 20 Januari 2025
A7: NO. | B7: NAMA | C7: TGL | E7: ANGSURAN PINJAMAN | I7: SISA | J7: SWK
E8: KE | F8: POKOK | G8: JASA | H8: JUMLAH
A9: 1 | B9: Suryadi | C9: 4-4-17 | D9: ='13-1-26'!I9 -> 5500000 | F9: 0 | G9: =SUM(E9:F9) -> 0 | H9: =SUM(F9:G9) -> 0 | I9: =D9-F9 -> 5500000 | J9: =1/10*G9 -> 0
A10: 2 | B10: Waginah | C10: 16-5-17 | D10: ='13-1-26'!I10 -> 1910000 | H10: =SUM(F10:G10) -> 0 | I10: =D10-F10 -> 1910000 | J10: =1/10*G10 -> 0
A11: 3 | B11: Tarmono | C11: 18-8-20 | D11: ='13-1-26'!I11 -> 1750000 | H11: =SUM(F11:G11) -> 0 | I11: =D11-F11 -> 1750000 | J11: =1/10*G11 -> 0
A12: 4 | B12: Juliyah | C12: 2-2-21 | D12: ='13-1-26'!I12 -> 13750000 | H12: =SUM(F12:G12) -> 0 | I12: =D12-F12 -> 13750000 | J12: =1/10*G12 -> 0
A13: 5 | B13: Purwadi | C13: 14-03-21 | D13: ='13-1-26'!I13 -> 19950000 | H13: =SUM(F13:G13) -> 0 | I13: =D13-F13 -> 19950000 | J13: =1/10*G13 -> 0
A14: 6 | B14: Waluyo Ragil | C14: 27-04-21 | D14: ='13-1-26'!I14 -> 100000 | H14: =SUM(F14:G14) -> 0 | I14: =D14-F14 -> 100000 | J14: =1/10*G14 -> 0
A15: 7 | B15: Sapdono | C15: 24-8-23 | D15: ='13-1-26'!I15 -> 10500000 | H15: =SUM(F15:G15) -> 0 | I15: =D15-F15 -> 10500000 | J15: =1/10*G15 -> 0
A16: 8 | B16: Sudarma Widya | C16: 28-09-21 | D16: ='13-1-26'!I16 -> 15310000 | H16: =SUM(F16:G16) -> 0 | I16: =D16-F16 -> 15310000 | J16: =1/10*G16 -> 0
A17: 9 | B17: Rahmadi | C17: 15-2-22 | D17: ='13-1-26'!I17 -> 6500000 | H17: =SUM(F17:G17) -> 0 | I17: =D17-F17 -> 6500000 | J17: =1/10*G17 -> 0
A18: 10 | B18: Ratmi | C18: 8-3-22 | D18: ='13-1-26'!I18 -> 13195000 | H18: =SUM(F18:G18) -> 0 | I18: =D18-F18 -> 13195000 | J18: =1/10*G18 -> 0
A19: 14 | B19: Cipret | C19: 21-6-22 | D19: ='13-1-26'!I19 -> 4000000 | H19: =SUM(F19:G19) -> 0 | I19: =D19-F19 -> 4000000 | J19: =1/10*G19 -> 0
A20: 18 | B20: Ika Kurniasih | C20: 03-1-22 | D20: ='13-1-26'!I20 -> 42000000 | H20: =SUM(F20:G20) -> 0 | I20: =D20-F20 -> 42000000 | J20: =1/10*G20 -> 0
A21: 19 | B21: Kamto | C21: 28-2-23 | D21: ='13-1-26'!I21 -> 12680000 | H21: =SUM(F21:G21) -> 0 | I21: =D21-F21 -> 12680000 | J21: =1/10*G21 -> 0
... A57: 94 | B57: Mislam | C57: 25/2/25 | D57: ='13-1-26'!I57 -> 20000000 | H57: =SUM(F57:G57) -> 0 | I57: =D57-F57 -> 20000000 | J57: =1/10*G57 -> 0
A58: 98 | B58: Lewih | C58: 25/3/25 | D58: ='13-1-26'!I58 -> 1985000 | E58: 10 | F58: 335000 | G58: 100000 | H58: =SUM(F58:G58) -> 435000 | I58: =D58-F58 -> 1650000 | J58: =1/10*G58 -> 10000
A59: 101 | B59: Rusmini Bolot | C59: 8/4/25 | D59: ='13-1-26'!I59 -> 0 | H59: =SUM(F59:G59) -> 0 | I59: =D59-F59 -> 0 | J59: =1/10*G59 -> 0
A60: 103 | B60: Kadi | C60: 15/4/25 | D60: ='13-1-26'!I60 -> 3250000 | H60: =SUM(F60:G60) -> 0 | I60: =D60-F60 -> 3250000 | J60: =1/10*G60 -> 0
A61: 106 | B61: Marsito | C61: 27-5-25 | D61: ='13-1-26'!I61 -> 230000 | H61: =SUM(F61:G61) -> 0 | I61: =D61-F61 -> 230000 | J61: =1/10*G61 -> 0
A62: 108 | B62: Darwito | C62: 10-6-25 | D62: ='13-1-26'!I62 -> 1000000 | E62: 6 | F62: 1000000 | G62: 120000 | H62: =SUM(F62:G62) -> 1120000 | I62: =D62-F62 -> 0 | J62: =1/10*G62 -> 12000
A63: 110 | B63: Manis | C63: 15r-7-25 | D63: ='13-1-26'!I63 -> 700000 | H63: =SUM(F63:G63) -> 0 | I63: =D63-F63 -> 700000 | J63: =1/10*G63 -> 0
A64: 111 | B64: Turyanto Madiono | C64: 12-8-25 | D64: ='13-1-26'!I64 -> 1500000 | H64: =SUM(F64:G64) -> 0 | I64: =D64-F64 -> 1500000 | J64: =1/10*G64 -> 0
A65: 112 | B65: Aniah Marsih | C65: 26/9/25 | D65: ='13-1-26'!I65 -> 6570000 | H65: =SUM(F65:G65) -> 0 | I65: =D65-F65 -> 6570000 | J65: =1/10*G65 -> 0
A66: 113 | B66: Ranem | C66: 26/9/25 | D66: ='13-1-26'!I66 -> 250000 | H66: =SUM(F66:G66) -> 0 | I66: =D66-F66 -> 250000 | J66: =1/10*G66 -> 0
A67: 117 | B67: Tato | C67: 18/11/25 | D67: ='13-1-26'!I67 -> 52000000 | E67: 1 | F67: 52000000 | G67: 2080000 | H67: =SUM(F67:G67) -> 54080000 | I67: =D67-F67 -> 0 | J67: =1/10*G67 -> 208000
J68: =1/10*G68 -> 0
J69: =1/10*G69 -> 0
J70: =1/10*G70 -> 0
J71: =1/10*G71 -> 0
J72: =1/10*G72 -> 0
J73: =1/10*G73 -> 0
J74: =1/10*G74 -> 0
J75: =1/10*G75 -> 0
J76: =1/10*G76 -> 0
...

Sheet 27-1-26
A1: KOPERASI SERBA USAHA "CAHAYA DHAMMA PHALA"
A2: Badan Hukum No. 2/BH/XIV.1/II/2016 Tanggal 5 Februari 2016
A3: Dukuh Windusari, Desa Sokaraja, Kec. Pagentan, Kab. Banjarnegara 53455
A5: BUKU ANGSURAN PINJAMAN ANGGOTA
A6: Per 27 Januari 2026
A7: NO. | B7: NAMA | C7: TGL | E7: ANGSURAN PINJAMAN | I7: SISA | J7: SWK
E8: KE | F8: POKOK | G8: JASA | H8: JUMLAH
A9: 1 | B9: Suryadi | C9: 4-4-17 | D9: ='20-1-26'!I9 -> 5500000 | F9: 0 | G9: =SUM(E9:F9) -> 0 | H9: =SUM(F9:G9) -> 0 | I9: =D9-F9 -> 5500000 | J9: =1/10*G9 -> 0
A10: 2 | B10: Waginah | C10: 16-5-17 | D10: ='20-1-26'!I10 -> 1910000 | H10: =SUM(F10:G10) -> 0 | I10: =D10-F10 -> 1910000 | J10: =1/10*G10 -> 0
A11: 3 | B11: Tarmono | C11: 18-8-20 | D11: ='20-1-26'!I11 -> 1750000 | H11: =SUM(F11:G11) -> 0 | I11: =D11-F11 -> 1750000 | J11: =1/10*G11 -> 0
A12: 4 | B12: Juliyah | C12: 2-2-21 | D12: ='20-1-26'!I12 -> 13750000 | H12: =SUM(F12:G12) -> 0 | I12: =D12-F12 -> 13750000 | J12: =1/10*G12 -> 0
A13: 5 | B13: Purwadi | C13: 14-03-21 | D13: ='20-1-26'!I13 -> 19950000 | H13: =SUM(F13:G13) -> 0 | I13: =D13-F13 -> 19950000 | J13: =1/10*G13 -> 0
A14: 6 | B14: Waluyo Ragil | C14: 27-04-21 | D14: ='20-1-26'!I14 -> 100000 | H14: =SUM(F14:G14) -> 0 | I14: =D14-F14 -> 100000 | J14: =1/10*G14 -> 0
A15: 7 | B15: Sapdono | C15: 24-8-23 | D15: ='20-1-26'!I15 -> 10500000 | H15: =SUM(F15:G15) -> 0 | I15: =D15-F15 -> 10500000 | J15: =1/10*G15 -> 0
A16: 8 | B16: Sudarma Widya | C16: 28-09-21 | D16: ='20-1-26'!I16 -> 15310000 | H16: =SUM(F16:G16) -> 0 | I16: =D16-F16 -> 15310000 | J16: =1/10*G16 -> 0
A17: 9 | B17: Rahmadi | C17: 15-2-22 | D17: ='20-1-26'!I17 -> 6500000 | H17: =SUM(F17:G17) -> 0 | I17: =D17-F17 -> 6500000 | J17: =1/10*G17 -> 0
A18: 10 | B18: Ratmi | C18: 8-3-22 | D18: ='20-1-26'!I18 -> 13195000 | E18: 10 | F18: 600000 | G18: 400000 | H18: =SUM(F18:G18) -> 1000000 | I18: =D18-F18 -> 12595000 | J18: =1/10*G18 -> 40000
A19: 14 | B19: Cipret | C19: 21-6-22 | D19: ='20-1-26'!I19 -> 4000000 | H19: =SUM(F19:G19) -> 0 | I19: =D19-F19 -> 4000000 | J19: =1/10*G19 -> 0
A20: 18 | B20: Ika Kurniasih | C20: 03-1-22 | D20: ='20-1-26'!I20 -> 42000000 | H20: =SUM(F20:G20) -> 0 | I20: =D20-F20 -> 42000000 | J20: =1/10*G20 -> 0
A21: 19 | B21: Kamto | C21: 28-2-23 | D21: ='20-1-26'!I21 -> 12680000 | H21: =SUM(F21:G21) -> 0 | I21: =D21-F21 -> 12680000 | J21: =1/10*G21 -> 0
A22: 22 | B22: Handi Cahyono | C22: 04-04-23 | D22: ='20-1-26'!I22 -> 0 | H22: =SUM(F22:G22) -> 0 | I22: =D22-F22 -> 0 | J22: =1/10*G22 -> 0
A23: 23 | B23: Hartati | C23: 04-04-23 | D23: ='20-1-26'!I23 -> 1500000 | H23: =SUM(F23:G23) -> 0 | I23: =D23-F23 -> 1500000 | J23: =1/10*G23 -> 0
A24: 24 | B24: Sartiyah | C24: 04-04-23 | D24: ='20-1-26'!I24 -> 600000 | H24: =SUM(F24:G24) -> 0 | I24: =D24-F24 -> 600000 | J24: =1/10*G24 -> 0
A25: 25 | B25: Dwi Vijjayanti | C25: 11-04-23 | D25: ='20-1-26'!I25 -> 22200000 | H25: =SUM(F25:G25) -> 0 | I25: =D25-F25 -> 22200000 | J25: =1/10*G25 -> 0
A26: 26 | B26: Marsinem | C26: 2-5-23 | D26: ='20-1-26'!I26 -> 3800000 | H26: =SUM(F26:G26) -> 0 | I26: =D26-F26 -> 3800000 | J26: =1/10*G26 -> 0
A27: 29 | B27: Suharjanto | C27: 11/7/23 | D27: ='20-1-26'!I27 -> 1030000 | H27: =SUM(F27:G27) -> 0 | I27: =D27-F27 -> 1030000 | J27: =1/10*G27 -> 0
A28: 30 | B28: Saliyah | C28: 18/7/23 | D28: ='20-1-26'!I28 -> 0 | H28: =SUM(F28:G28) -> 0 | I28: =D28-F28 -> 0 | J28: =1/10*G28 -> 0
A29: 31 | B29: Suminah | C29: 26-9-23 | D29: ='20-1-26'!I29 -> 0 | H29: =SUM(F29:G29) -> 0 | I29: =D29-F29 -> 0 | J29: =1/10*G29 -> 0
A30: 33 | B30: Leni | C30: 10-10-23 | D30: ='20-1-26'!I30 -> 2750000 | H30: =SUM(F30:G30) -> 0 | I30: =D30-F30 -> 2750000 | J30: =1/10*G30 -> 0
... A50: 82 | B50: Saroji | C50: 17/12/24 | D50: ='20-1-26'!I50 -> 0 | H50: =SUM(F50:G50) -> 0 | I50: =D50-F50 -> 0 | J50: =1/10*G50 -> 0
A51: 86 | B51: Minardi | C51: 21/1/25 | D51: ='20-1-26'!I51 -> 16400000 | G51: 400000 | H51: =SUM(F51:G51) -> 400000 | I51: =D51-F51 -> 16400000 | J51: =1/10*G51 -> 40000
A52: 87 | B52: Kuat Siti Kirana | C52: 28/1/25 | D52: ='20-1-26'!I52 -> 25400000 | H52: =SUM(F52:G52) -> 0 | I52: =D52-F52 -> 25400000 | J52: =1/10*G52 -> 0
A53: 89 | B53: Vijja Ratano | C53: 18/2/25 | D53: ='20-1-26'!I53 -> 100000 | H53: =SUM(F53:G53) -> 0 | I53: =D53-F53 -> 100000 | J53: =1/10*G53 -> 0
A54: 91 | B54: Suroto | C54: 18/2/25 | D54: ='20-1-26'!I54 -> 5000000 | E54: 2 | F54: 200000 | G54: 100000 | H54: =SUM(F54:G54) -> 300000 | I54: =D54-F54 -> 4800000 | J54: =1/10*G54 -> 10000
A55: 92 | B55: Sono | C55: 25/2/25 | D55: ='20-1-26'!I55 -> 7460000 | H55: =SUM(F55:G55) -> 0 | I55: =D55-F55 -> 7460000 | J55: =1/10*G55 -> 0
A56: 93 | B56: Metta Candra D. | C56: 25/2/25 | D56: ='20-1-26'!I56 -> 600000 | H56: =SUM(F56:G56) -> 0 | I56: =D56-F56 -> 600000 | J56: =1/10*G56 -> 0
A57: 94 | B57: Mislam | C57: 25/2/25 | D57: ='20-1-26'!I57 -> 20000000 | H57: =SUM(F57:G57) -> 0 | I57: =D57-F57 -> 20000000 | J57: =1/10*G57 -> 0
A58: 98 | B58: Lewih | C58: 25/3/25 | D58: ='20-1-26'!I58 -> 1650000 | H58: =SUM(F58:G58) -> 0 | I58: =D58-F58 -> 1650000 | J58: =1/10*G58 -> 0
A59: 101 | B59: Rusmini Bolot | C59: 8/4/25 | D59: ='20-1-26'!I59 -> 0 | H59: =SUM(F59:G59) -> 0 | I59: =D59-F59 -> 0 | J59: =1/10*G59 -> 0
A60: 103 | B60: Kadi | C60: 15/4/25 | D60: ='20-1-26'!I60 -> 3250000 | H60: =SUM(F60:G60) -> 0 | I60: =D60-F60 -> 3250000 | J60: =1/10*G60 -> 0
...

Sheet 3-2-26
A1: KOPERASI SERBA USAHA "CAHAYA DHAMMA PHALA"
A2: Badan Hukum No. 2/BH/XIV.1/II/2016 Tanggal 5 Februari 2016
A3: Dukuh Windusari, Desa Sokaraja, Kec. Pagentan, Kab. Banjarnegara 53455
A5: BUKU ANGSURAN PINJAMAN ANGGOTA
A6: Per 3 Februari 2026
A7: NO. | B7: NAMA | C7: TGL | E7: ANGSURAN PINJAMAN | I7: SISA | J7: SWK
E8: KE | F8: POKOK | G8: JASA | H8: JUMLAH
A9: 1 | B9: Suryadi | C9: 4-4-17 | D9: ='27-1-26'!I9 -> 5500000 | F9: 0 | G9: =SUM(E9:F9) -> 0 | H9: =SUM(F9:G9) -> 0 | I9: =D9-F9 -> 5500000 | J9: =1/10*G9 -> 0
A10: 2 | B10: Waginah | C10: 16-5-17 | D10: ='27-1-26'!I10 -> 1910000 | H10: =SUM(F10:G10) -> 0 | I10: =D10-F10 -> 1910000 | J10: =1/10*G10 -> 0
A11: 3 | B11: Tarmono | C11: 18-8-20 | D11: ='27-1-26'!I11 -> 1750000 | H11: =SUM(F11:G11) -> 0 | I11: =D11-F11 -> 1750000 | J11: =1/10*G11 -> 0
A12: 4 | B12: Juliyah | C12: 2-2-21 | D12: ='27-1-26'!I12 -> 13750000 | H12: =SUM(F12:G12) -> 0 | I12: =D12-F12 -> 13750000 | J12: =1/10*G12 -> 0
A13: 5 | B13: Purwadi | C13: 14-03-21 | D13: ='27-1-26'!I13 -> 19950000 | H13: =SUM(F13:G13) -> 0 | I13: =D13-F13 -> 19950000 | J13: =1/10*G13 -> 0
A14: 6 | B14: Waluyo Ragil | C14: 27-04-21 | D14: ='27-1-26'!I14 -> 100000 | H14: =SUM(F14:G14) -> 0 | I14: =D14-F14 -> 100000 | J14: =1/10*G14 -> 0
A15: 7 | B15: Sapdono | C15: 24-8-23 | D15: ='27-1-26'!I15 -> 10500000 | H15: =SUM(F15:G15) -> 0 | I15: =D15-F15 -> 10500000 | J15: =1/10*G15 -> 0
A16: 8 | B16: Sudarma Widya | C16: 28-09-21 | D16: ='27-1-26'!I16 -> 15310000 | H16: =SUM(F16:G16) -> 0 | I16: =D16-F16 -> 15310000 | J16: =1/10*G16 -> 0
A17: 9 | B17: Rahmadi | C17: 15-2-22 | D17: ='27-1-26'!I17 -> 6500000 | H17: =SUM(F17:G17) -> 0 | I17: =D17-F17 -> 6500000 | J17: =1/10*G17 -> 0
A18: 10 | B18: Ratmi | C18: 8-3-22 | D18: ='27-1-26'!I18 -> 12595000 | H18: =SUM(F18:G18) -> 0 | I18: =D18-F18 -> 12595000 | J18: =1/10*G18 -> 0
A19: 14 | B19: Cipret | C19: 21-6-22 | D19: ='27-1-26'!I19 -> 4000000 | H19: =SUM(F19:G19) -> 0 | I19: =D19-F19 -> 4000000 | J19: =1/10*G19 -> 0
A20: 18 | B20: Ika Kurniasih | C20: 03-1-22 | D20: ='27-1-26'!I20 -> 42000000 | H20: =SUM(F20:G20) -> 0 | I20: =D20-F20 -> 42000000 | J20: =1/10*G20 -> 0
A21: 19 | B21: Kamto | C21: 28-2-23 | D21: ='27-1-26'!I21 -> 12680000 | H21: =SUM(F21:G21) -> 0 | I21: =D21-F21 -> 12680000 | J21: =1/10*G21 -> 0
... A35: 44 | B35: Karsih | C35: 30/1/24 | D35: ='27-1-26'!I35 -> 3500000 | H35: =SUM(F35:G35) -> 0 | I35: =D35-F35 -> 3500000 | J35: =1/10*G35 -> 0
A36: 47 | B36: Painten Darwito | C36: 16/2/24 | D36: ='27-1-26'!I36 -> 12000000 | E36: 21 | F36: 1400000 | G36: 800000 | H36: =SUM(F36:G36) -> 2200000 | I36: =D36-F36 -> 10600000 | J36: =1/10*G36 -> 80000
A37: 49 | B37: Karni | C37: 2/4/24 | D37: ='27-1-26'!I37 -> 1250000 | H37: =SUM(F37:G37) -> 0 | I37: =D37-F37 -> 1250000 | J37: =1/10*G37 -> 0
A38: 52 | B38: Siyo Dwiroso | C38: 16/4/24 | D38: ='27-1-26'!I38 -> 5800000 | H38: =SUM(F38:G38) -> 0 | I38: =D38-F38 -> 5800000 | J38: =1/10*G38 -> 0
A39: 60 | B39: Purwati | C39: 4/6/24 | D39: ='27-1-26'!I39 -> 14320000 | H39: =SUM(F39:G39) -> 0 | I39: =D39-F39 -> 14320000 | J39: =1/10*G39 -> 0
A40: 62 | B40: Tarsini | C40: 02/07/24 | D40: ='27-1-26'!I40 -> 400000 | H40: =SUM(F40:G40) -> 0 | I40: =D40-F40 -> 400000 | J40: =1/10*G40 -> 0
A41: 64 | B41: Santosa | C41: 09/07/24 | D41: ='27-1-26'!I41 -> 1800000 | H41: =SUM(F41:G41) -> 0 | I41: =D41-F41 -> 1800000 | J41: =1/10*G41 -> 0
A42: 65 | B42: Priyono | C42: 16/07/24 | D42: ='27-1-26'!I42 -> 1200000 | H42: =SUM(F42:G42) -> 0 | I42: =D42-F42 -> 1200000 | J42: =1/10*G42 -> 0
A43: 69 | B43: Karyono | C43: 30/07/24 | D43: ='27-1-26'!I43 -> 6000000 | E43: 14 | F43: 750000 | G43: 300000 | H43: =SUM(F43:G43) -> 1050000 | I43: =D43-F43 -> 5250000 | J43: =1/10*G43 -> 30000
A44: 70 | B44: Dwiyanto | C44: 06/08/24 | D44: ='27-1-26'!I44 -> 10320000 | H44: =SUM(F44:G44) -> 0 | I44: =D44-F44 -> 10320000 | J44: =1/10*G44 -> 0
A45: 71 | B45: Utami | C45: 20/08/24 | D45: ='27-1-26'!I45 -> 11250000 | E45: 11 | F45: 375000 | G45: 300000 | H45: =SUM(F45:G45) -> 675000 | I45: =D45-F45 -> 10875000 | J45: =1/10*G45 -> 30000
A46: 73 | B46: Karjono | C46: 10/09/24 | D46: ='27-1-26'!I46 -> 600000 | H46: =SUM(F46:G46) -> 0 | I46: =D46-F46 -> 600000 | J46: =1/10*G46 -> 0
A47: 76 | B47: Kuswono Katam | C47: 05/11/24 | D47: ='27-1-26'!I47 -> 9600000 | H47: =SUM(F47:G47) -> 0 | I47: =D47-F47 -> 9600000 | J47: =1/10*G47 -> 0
A48: 77 | B48: Sarijem | C48: 05/11/24 | D48: ='27-1-26'!I48 -> 1200000 | H48: =SUM(F48:G48) -> 0 | I48: =D48-F48 -> 1200000 | J48: =1/10*G48 -> 0
A49: 80 | B49: Nisem | C49: 03/12/24 | D49: ='27-1-26'!I49 -> 9900000 | H49: =SUM(F49:G49) -> 0 | I49: =D49-F49 -> 9900000 | J49: =1/10*G49 -> 0
A50: 82 | B50: Saroji | C50: 17/12/24 | D50: ='27-1-26'!I50 -> 0 | H50: =SUM(F50:G50) -> 0 | I50: =D50-F50 -> 0 | J50: =1/10*G50 -> 0
A51: 86 | B51: Minardi | C51: 21/1/25 | D51: ='27-1-26'!I51 -> 16400000 | H51: =SUM(F51:G51) -> 0 | I51: =D51-F51 -> 16400000 | J51: =1/10*G51 -> 0
A52: 87 | B52: Kuat Siti Kirana | C52: 28/1/25 | D52: ='27-1-26'!I52 -> 25400000 | E52: 7 | F52: 400000 | G52: 600000 | H52: =SUM(F52:G52) -> 1000000 | I52: =D52-F52 -> 25000000 | J52: =1/10*G52 -> 60000
A53: 89 | B53: Vijja Ratano | C53: 18/2/25 | D53: ='27-1-26'!I53 -> 100000 | H53: =SUM(F53:G53) -> 0 | I53: =D53-F53 -> 100000 | J53: =1/10*G53 -> 0
A54: 91 | B54: Suroto | C54: 18/2/25 | D54: ='27-1-26'!I54 -> 4800000 | H54: =SUM(F54:G54) -> 0 | I54: =D54-F54 -> 4800000 | J54: =1/10*G54 -> 0
...

Sheet 10-2-26
A1: KOPERASI SERBA USAHA "CAHAYA DHAMMA PHALA"
A2: Badan Hukum No. 2/BH/XIV.1/II/2016 Tanggal 5 Februari 2016
A3: Dukuh Windusari, Desa Sokaraja, Kec. Pagentan, Kab. Banjarnegara 53455
A5: BUKU ANGSURAN PINJAMAN ANGGOTA
A6: Per 10 Februari 2026
A7: NO. | B7: NAMA | C7: TGL | E7: ANGSURAN PINJAMAN | I7: SISA | J7: SWK
E8: KE | F8: POKOK | G8: JASA | H8: JUMLAH
A9: 1 | B9: Suryadi | C9: 4-4-17 | D9: ='3-2-26'!I9 -> 5500000 | F9: 0 | G9: =SUM(E9:F9) -> 0 | H9: =SUM(F9:G9) -> 0 | I9: =D9-F9 -> 5500000 | J9: =1/10*G9 -> 0
A10: 2 | B10: Waginah | C10: 16-5-17 | D10: ='3-2-26'!I10 -> 1910000 | H10: =SUM(F10:G10) -> 0 | I10: =D10-F10 -> 1910000 | J10: =1/10*G10 -> 0
A11: 3 | B11: Tarmono | C11: 18-8-20 | D11: ='3-2-26'!I11 -> 1750000 | H11: =SUM(F11:G11) -> 0 | I11: =D11-F11 -> 1750000 | J11: =1/10*G11 -> 0
A12: 4 | B12: Juliyah | C12: 2-2-21 | D12: ='3-2-26'!I12 -> 13750000 | H12: =SUM(F12:G12) -> 0 | I12: =D12-F12 -> 13750000 | J12: =1/10*G12 -> 0
A13: 5 | B13: Purwadi | C13: 14-03-21 | D13: ='3-2-26'!I13 -> 19950000 | H13: =SUM(F13:G13) -> 0 | I13: =D13-F13 -> 19950000 | J13: =1/10*G13 -> 0
A14: 6 | B14: Waluyo Ragil | C14: 27-04-21 | D14: ='3-2-26'!I14 -> 100000 | H14: =SUM(F14:G14) -> 0 | I14: =D14-F14 -> 100000 | J14: =1/10*G14 -> 0
A15: 7 | B15: Sapdono | C15: 24-8-23 | D15: ='3-2-26'!I15 -> 10500000 | H15: =SUM(F15:G15) -> 0 | I15: =D15-F15 -> 10500000 | J15: =1/10*G15 -> 0
A16: 8 | B16: Sudarma Widya | C16: 28-09-21 | D16: ='3-2-26'!I16 -> 15310000 | H16: =SUM(F16:G16) -> 0 | I16: =D16-F16 -> 15310000 | J16: =1/10*G16 -> 0
A17: 9 | B17: Rahmadi | C17: 15-2-22 | D17: ='3-2-26'!I17 -> 6500000 | E17: 11 | F17: 350000 | G17: 200000 | H17: =SUM(F17:G17) -> 550000 | I17: =D17-F17 -> 6150000 | J17: =1/10*G17 -> 20000
A18: 10 | B18: Ratmi | C18: 8-3-22 | D18: ='3-2-26'!I18 -> 12595000 | H18: =SUM(F18:G18) -> 0 | I18: =D18-F18 -> 12595000 | J18: =1/10*G18 -> 0
A19: 14 | B19: Cipret | C19: 21-6-22 | D19: ='3-2-26'!I19 -> 4000000 | E19: 5 | F19: 250000 | G19: 100000 | H19: =SUM(F19:G19) -> 350000 | I19: =D19-F19 -> 3750000 | J19: =1/10*G19 -> 10000
A20: 18 | B20: Ika Kurniasih | C20: 03-1-22 | D20: ='3-2-26'!I20 -> 42000000 | H20: =SUM(F20:G20) -> 0 | I20: =D20-F20 -> 42000000 | J20: =1/10*G20 -> 0
A21: 19 | B21: Kamto | C21: 28-2-23 | D21: ='3-2-26'!I21 -> 12680000 | H21: =SUM(F21:G21) -> 0 | I21: =D21-F21 -> 12680000 | J21: =1/10*G21 -> 0
A22: 22 | B22: Handi Cahyono | C22: 04-04-23 | D22: ='3-2-26'!I22 -> 0 | H22: =SUM(F22:G22) -> 0 | I22: =D22-F22 -> 0 | J22: =1/10*G22 -> 0
A23: 23 | B23: Hartati | C23: 04-04-23 | D23: ='3-2-26'!I23 -> 1500000 | H23: =SUM(F23:G23) -> 0 | I23: =D23-F23 -> 1500000 | J23: =1/10*G23 -> 0
A24: 24 | B24: Sartiyah | C24: 04-04-23 | D24: ='3-2-26'!I24 -> 600000 | H24: =SUM(F24:G24) -> 0 | I24: =D24-F24 -> 600000 | J24: =1/10*G24 -> 0
A25: 25 | B25: Dwi Vijjayanti | C25: 11-04-23 | D25: ='3-2-26'!I25 -> 22200000 | H25: =SUM(F25:G25) -> 0 | I25: =D25-F25 -> 22200000 | J25: =1/10*G25 -> 0
A26: 26 | B26: Marsinem | C26: 2-5-23 | D26: ='3-2-26'!I26 -> 3800000 | H26: =SUM(F26:G26) -> 0 | I26: =D26-F26 -> 3800000 | J26: =1/10*G26 -> 0
A27: 29 | B27: Suharjanto | C27: 11/7/23 | D27: ='3-2-26'!I27 -> 1030000 | H27: =SUM(F27:G27) -> 0 | I27: =D27-F27 -> 1030000 | J27: =1/10*G27 -> 0
A28: 30 | B28: Saliyah | C28: 18/7/23 | D28: ='3-2-26'!I28 -> 0 | H28: =SUM(F28:G28) -> 0 | I28: =D28-F28 -> 0 | J28: =1/10*G28 -> 0
A29: 31 | B29: Suminah | C29: 26-9-23 | D29: ='3-2-26'!I29 -> 0 | H29: =SUM(F29:G29) -> 0 | I29: =D29-F29 -> 0 | J29: =1/10*G29 -> 0
A30: 33 | B30: Leni | C30: 10-10-23 | D30: ='3-2-26'!I30 -> 2750000 | H30: =SUM(F30:G30) -> 0 | I30: =D30-F30 -> 2750000 | J30: =1/10*G30 -> 0
A31: 34 | B31: Kasmi Purwadi | C31: 24-10-23 | D31: ='3-2-26'!I31 -> 1250000 | H31: =SUM(F31:G31) -> 0 | I31: =D31-F31 -> 1250000 | J31: =1/10*G31 -> 0
A32: 35 | B32: Gini Wanto | C32: 24-10-23 | D32: ='3-2-26'!I32 -> 12000000 | H32: =SUM(F32:G32) -> 0 | I32: =D32-F32 -> 12000000 | J32: =1/10*G32 -> 0
A33: 41 | B33: Kami | C33: 9/1/24 | D33: ='3-2-26'!I33 -> 750000 | E33: 16 | F33: 150000 | G33: 60000 | H33: =SUM(F33:G33) -> 210000 | I33: =D33-F33 -> 600000 | J33: =1/10*G33 -> 6000
A34: 43 | B34: Wahyuni | C34: 30/1/24 | D34: ='3-2-26'!I34 -> 2800000 | H34: =SUM(F34:G34) -> 0 | I34: =D34-F34 -> 2800000 | J34: =1/10*G34 -> 0
A35: 44 | B35: Karsih | C35: 30/1/24 | D35: ='3-2-26'!I35 -> 3500000 | H35: =SUM(F35:G35) -> 0 | I35: =D35-F35 -> 3500000 | J35: =1/10*G35 -> 0
A36: 47 | B36: Painten Darwito | C36: 16/2/24 | D36: ='3-2-26'!I36 -> 10600000 | H36: =SUM(F36:G36) -> 0 | I36: =D36-F36 -> 10600000 | J36: =1/10*G36 -> 0
A37: 49 | B37: Karni | C37: 2/4/24 | D37: ='3-2-26'!I37 -> 1250000 | H37: =SUM(F37:G37) -> 0 | I37: =D37-F37 -> 1250000 | J37: =1/10*G37 -> 0
A38: 52 | B38: Siyo Dwiroso | C38: 16/4/24 | D38: ='3-2-26'!I38 -> 5800000 | H38: =SUM(F38:G38) -> 0 | I38: =D38-F38 -> 5800000 | J38: =1/10*G38 -> 0
A39: 60 | B39: Purwati | C39: 4/6/24 | D39: ='3-2-26'!I39 -> 14320000 | H39: =SUM(F39:G39) -> 0 | I39: =D39-F39 -> 14320000 | J39: =1/10*G39 -> 0
A40: 62 | B40: Tarsini | C40: 02/07/24 | D40: ='3-2-26'!I40 -> 400000 | E40: 14 | F40: 200000 | G40: 60000 | H40: =SUM(F40:G40) -> 260000 | I40: =D40-F40 -> 200000 | J40: =1/10*G40 -> 6000
A41: 64 | B41: Santosa | C41: 09/07/24 | D41: ='3-2-26'!I41 -> 1800000 | H41: =SUM(F41:G41) -> 0 | I41: =D41-F41 -> 1800000 | J41: =1/10*G41 -> 0
...

Sheet 13-2-26
A1: KOPERASI SERBA USAHA "CAHAYA DHAMMA PHALA"
A2: Badan Hukum No. 2/BH/XIV.1/II/2016 Tanggal 5 Februari 2016
A3: Dukuh Windusari, Desa Sokaraja, Kec. Pagentan, Kab. Banjarnegara 53455
A5: BUKU ANGSURAN PINJAMAN ANGGOTA
A6: Per 13 Februari 2026
A7: NO. | B7: NAMA | C7: TGL | E7: ANGSURAN PINJAMAN | I7: SISA | J7: SWK
E8: KE | F8: POKOK | G8: JASA | H8: JUMLAH
A9: 1 | B9: Suryadi | C9: 4-4-17 | D9: ='10-2-26'!I9 -> 5500000 | I9: =D9-F9 -> 5500000 | J9: =1/10*G9 -> 0
A10: 2 | B10: Waginah | C10: 16-5-17 | D10: ='10-2-26'!I10 -> 1910000 | I10: =D10-F10 -> 1910000 | J10: =1/10*G10 -> 0
A11: 3 | B11: Tarmono | C11: 18-8-20 | D11: ='10-2-26'!I11 -> 1750000 | E11: 10 | F11: 1750000 | G11: 2900000 | H11: =SUM(F11:G11) -> 4650000 | I11: =D11-F11 -> 0 | J11: =1/10*G11 -> 290000
A12: 4 | B12: Juliyah | C12: 2-2-21 | D12: ='10-2-26'!I12 -> 13750000 | I12: =D12-F12 -> 13750000 | J12: =1/10*G12 -> 0
A13: 5 | B13: Purwadi | C13: 14-03-21 | D13: ='10-2-26'!I13 -> 19950000 | I13: =D13-F13 -> 19950000 | J13: =1/10*G13 -> 0
A14: 6 | B14: Waluyo Ragil | C14: 27-04-21 | D14: ='10-2-26'!I14 -> 100000 | I14: =D14-F14 -> 100000 | J14: =1/10*G14 -> 0
A15: 7 | B15: Sapdono | C15: 24-8-23 | D15: ='10-2-26'!I15 -> 10500000 | I15: =D15-F15 -> 10500000 | J15: =1/10*G15 -> 0
A16: 8 | B16: Sudarma Widya | C16: 28-09-21 | D16: ='10-2-26'!I16 -> 15310000 | I16: =D16-F16 -> 15310000 | J16: =1/10*G16 -> 0
A17: 9 | B17: Rahmadi | C17: 15-2-22 | D17: ='10-2-26'!I17 -> 6150000 | I17: =D17-F17 -> 6150000 | J17: =1/10*G17 -> 0
A18: 10 | B18: Ratmi | C18: 8-3-22 | D18: ='10-2-26'!I18 -> 12595000 | I18: =D18-F18 -> 12595000 | J18: =1/10*G18 -> 0
A19: 14 | B19: Cipret | C19: 21-6-22 | D19: ='10-2-26'!I19 -> 3750000 | I19: =D19-F19 -> 3750000 | J19: =1/10*G19 -> 0
A20: 18 | B20: Ika Kurniasih | C20: 03-1-22 | D20: ='10-2-26'!I20 -> 42000000 | I20: =D20-F20 -> 42000000 | J20: =1/10*G20 -> 0
A21: 19 | B21: Kamto | C21: 28-2-23 | D21: ='10-2-26'!I21 -> 12680000 | I21: =D21-F21 -> 12680000 | J21: =1/10*G21 -> 0
A22: 22 | B22: Handi Cahyono | C22: 04-04-23 | D22: ='10-2-26'!I22 -> 0 | I22: =D22-F22 -> 0 | J22: =1/10*G22 -> 0
A23: 23 | B23: Hartati | C23: 04-04-23 | D23: ='10-2-26'!I23 -> 1500000 | I23: =D23-F23 -> 1500000 | J23: =1/10*G23 -> 0
... A46: 73 | B46: Karjono | C46: 10/09/24 | D46: ='10-2-26'!I46 -> 450000 | I46: =D46-F46 -> 450000 | J46: =1/10*G46 -> 0
A47: 76 | B47: Kuswono Katam | C47: 05/11/24 | D47: ='10-2-26'!I47 -> 9600000 | H47: =SUM(F47:G47) -> 0 | I47: =D47-F47 -> 9600000 | J47: =1/10*G47 -> 0
A48: 77 | B48: Sarijem | C48: 05/11/24 | D48: ='10-2-26'!I48 -> 1200000 | H48: =SUM(F48:G48) -> 0 | I48: =D48-F48 -> 1200000 | J48: =1/10*G48 -> 0
A49: 80 | B49: Nisem | C49: 03/12/24 | D49: ='10-2-26'!I49 -> 9900000 | H49: =SUM(F49:G49) -> 0 | I49: =D49-F49 -> 9900000 | J49: =1/10*G49 -> 0
A50: 82 | B50: Saroji | C50: 17/12/24 | D50: ='10-2-26'!I50 -> 0 | H50: =SUM(F50:G50) -> 0 | I50: =D50-F50 -> 0 | J50: =1/10*G50 -> 0
A51: 86 | B51: Minardi | C51: 21/1/25 | D51: ='10-2-26'!I51 -> 16400000 | H51: =SUM(F51:G51) -> 0 | I51: =D51-F51 -> 16400000 | J51: =1/10*G51 -> 0
A52: 87 | B52: Kuat Siti Kirana | C52: 28/1/25 | D52: ='10-2-26'!I52 -> 25000000 | H52: =SUM(F52:G52) -> 0 | I52: =D52-F52 -> 25000000 | J52: =1/10*G52 -> 0
A53: 89 | B53: Vijja Ratano | C53: 18/2/25 | D53: ='10-2-26'!I53 -> 100000 | H53: =SUM(F53:G53) -> 0 | I53: =D53-F53 -> 100000 | J53: =1/10*G53 -> 0
A54: 91 | B54: Suroto | C54: 18/2/25 | D54: ='10-2-26'!I54 -> 4800000 | H54: =SUM(F54:G54) -> 0 | I54: =D54-F54 -> 4800000 | J54: =1/10*G54 -> 0
A55: 92 | B55: Sono | C55: 25/2/25 | D55: ='10-2-26'!I55 -> 7460000 | H55: =SUM(F55:G55) -> 0 | I55: =D55-F55 -> 7460000 | J55: =1/10*G55 -> 0
A56: 93 | B56: Metta Candra D. | C56: 25/2/25 | D56: ='10-2-26'!I56 -> 600000 | H56: =SUM(F56:G56) -> 0 | I56: =D56-F56 -> 600000 | J56: =1/10*G56 -> 0
A57: 94 | B57: Mislam | C57: 25/2/25 | D57: ='10-2-26'!I57 -> 20000000 | H57: =SUM(F57:G57) -> 0 | I57: =D57-F57 -> 20000000 | J57: =1/10*G57 -> 0
A58: 98 | B58: Lewih | C58: 25/3/25 | D58: ='10-2-26'!I58 -> 1650000 | H58: =SUM(F58:G58) -> 0 | I58: =D58-F58 -> 1650000 | J58: =1/10*G58 -> 0
... A67: 117 | B67: Tato | C67: 18/11/25 | D67: ='10-2-26'!I67 -> 0 | H67: =SUM(F67:G67) -> 0 | I67: =D67-F67 -> 0 | J67: =1/10*G67 -> 0
D68: ='10-2-26'!I68 -> 0 | H68: =SUM(F68:G68) -> 0 | J68: =1/10*G68 -> 0
D69: ='10-2-26'!I69 -> 0 | H69: =SUM(F69:G69) -> 0 | J69: =1/10*G69 -> 0
D70: ='10-2-26'!I70 -> 0 | H70: =SUM(F70:G70) -> 0 | J70: =1/10*G70 -> 0
D71: ='3-2-26'!I71 -> 0 | H71: =SUM(F71:G71) -> 0 | J71: =1/10*G71 -> 0
...

Sheet 17-2-26
A1: KOPERASI SERBA USAHA "CAHAYA DHAMMA PHALA"
A2: Badan Hukum No. 2/BH/XIV.1/II/2016 Tanggal 5 Februari 2016
A3: Dukuh Windusari, Desa Sokaraja, Kec. Pagentan, Kab. Banjarnegara 53455
A5: BUKU ANGSURAN PINJAMAN ANGGOTA
A6: Per 17 Februari 2026
A7: NO. | B7: NAMA | C7: TGL | E7: ANGSURAN PINJAMAN | I7: SISA | J7: SWK
E8: KE | F8: POKOK | G8: JASA | H8: JUMLAH
A9: 1 | B9: Suryadi | C9: 4-4-17 | D9: ='13-2-26'!I9 -> 5500000 | H9: =SUM(F9:G9) -> 0 | I9: =D9-F9 -> 5500000 | J9: =1/10*G9 -> 0
A10: 2 | B10: Waginah | C10: 16-5-17 | D10: ='13-2-26'!I10 -> 1910000 | H10: =SUM(F10:G10) -> 0 | I10: =D10-F10 -> 1910000 | J10: =1/10*G10 -> 0
A11: 3 | B11: Tarmono | C11: 18-8-20 | D11: ='13-2-26'!I11 -> 0 | H11: =SUM(F11:G11) -> 0 | I11: =D11-F11 -> 0 | J11: =1/10*G11 -> 0
A12: 4 | B12: Juliyah | C12: 2-2-21 | D12: ='13-2-26'!I12 -> 13750000 | H12: =SUM(F12:G12) -> 0 | I12: =D12-F12 -> 13750000 | J12: =1/10*G12 -> 0
A13: 5 | B13: Purwadi | C13: 14-03-21 | D13: ='13-2-26'!I13 -> 19950000 | H13: =SUM(F13:G13) -> 0 | I13: =D13-F13 -> 19950000 | J13: =1/10*G13 -> 0
A14: 6 | B14: Waluyo Ragil | C14: 27-04-21 | D14: ='13-2-26'!I14 -> 100000 | H14: =SUM(F14:G14) -> 0 | I14: =D14-F14 -> 100000 | J14: =1/10*G14 -> 0
A15: 7 | B15: Sapdono | C15: 24-8-23 | D15: ='13-2-26'!I15 -> 10500000 | H15: =SUM(F15:G15) -> 0 | I15: =D15-F15 -> 10500000 | J15: =1/10*G15 -> 0
A16: 8 | B16: Sudarma Widya | C16: 28-09-21 | D16: ='13-2-26'!I16 -> 15310000 | H16: =SUM(F16:G16) -> 0 | I16: =D16-F16 -> 15310000 | J16: =1/10*G16 -> 0
A17: 9 | B17: Rahmadi | C17: 15-2-22 | D17: ='13-2-26'!I17 -> 6150000 | H17: =SUM(F17:G17) -> 0 | I17: =D17-F17 -> 6150000 | J17: =1/10*G17 -> 0
A18: 10 | B18: Ratmi | C18: 8-3-22 | D18: ='13-2-26'!I18 -> 12595000 | H18: =SUM(F18:G18) -> 0 | I18: =D18-F18 -> 12595000 | J18: =1/10*G18 -> 0
A19: 14 | B19: Cipret | C19: 21-6-22 | D19: ='13-2-26'!I19 -> 3750000 | H19: =SUM(F19:G19) -> 0 | I19: =D19-F19 -> 3750000 | J19: =1/10*G19 -> 0
A20: 18 | B20: Ika Kurniasih | C20: 03-1-22 | D20: ='13-2-26'!I20 -> 42000000 | H20: =SUM(F20:G20) -> 0 | I20: =D20-F20 -> 42000000 | J20: =1/10*G20 -> 0
... A26: 26 | B26: Marsinem | C26: 2-5-23 | D26: ='13-2-26'!I26 -> 3800000 | H26: =SUM(F26:G26) -> 0 | I26: =D26-F26 -> 3800000 | J26: =1/10*G26 -> 0
A27: 29 | B27: Suharjanto | C27: 11/7/23 | D27: ='13-2-26'!I27 -> 1030000 | E27: 12 | F27: 270000 | G27: 80000 | H27: =SUM(F27:G27) -> 350000 | I27: =D27-F27 -> 760000 | J27: =1/10*G27 -> 8000
A28: 30 | B28: Saliyah | C28: 18/7/23 | D28: ='13-2-26'!I28 -> 0 | H28: =SUM(F28:G28) -> 0 | I28: =D28-F28 -> 0 | J28: =1/10*G28 -> 0
A29: 31 | B29: Suminah | C29: 26-9-23 | D29: ='13-2-26'!I29 -> 0 | H29: =SUM(F29:G29) -> 0 | I29: =D29-F29 -> 0 | J29: =1/10*G29 -> 0
A30: 33 | B30: Leni | C30: 10-10-23 | D30: ='13-2-26'!I30 -> 2750000 | H30: =SUM(F30:G30) -> 0 | I30: =D30-F30 -> 2750000 | J30: =1/10*G30 -> 0
A31: 34 | B31: Kasmi Purwadi | C31: 24-10-23 | D31: ='13-2-26'!I31 -> 1250000 | E31: 16 | F31: 250000 | G31: 100000 | H31: =SUM(F31:G31) -> 350000 | I31: =D31-F31 -> 1000000 | J31: =1/10*G31 -> 10000
A32: 35 | B32: Gini Wanto | C32: 24-10-23 | D32: ='13-2-26'!I32 -> 12000000 | H32: =SUM(F32:G32) -> 0 | I32: =D32-F32 -> 12000000 | J32: =1/10*G32 -> 0
A33: 41 | B33: Kami | C33: 9/1/24 | D33: ='13-2-26'!I33 -> 600000 | H33: =SUM(F33:G33) -> 0 | I33: =D33-F33 -> 600000 | J33: =1/10*G33 -> 0
A34: 43 | B34: Wahyuni | C34: 30/1/24 | D34: ='13-2-26'!I34 -> 2800000 | H34: =SUM(F34:G34) -> 0 | I34: =D34-F34 -> 2800000 | J34: =1/10*G34 -> 0
A35: 44 | B35: Karsih | C35: 30/1/24 | D35: ='13-2-26'!I35 -> 3500000 | H35: =SUM(F35:G35) -> 0 | I35: =D35-F35 -> 3500000 | J35: =1/10*G35 -> 0
A36: 47 | B36: Painten Darwito | C36: 16/2/24 | D36: ='13-2-26'!I36 -> 10600000 | E36: 22 | F36: 1400000 | G36: 800000 | H36: =SUM(F36:G36) -> 2200000 | I36: =D36-F36 -> 9200000 | J36: =1/10*G36 -> 80000
A37: 49 | B37: Karni | C37: 2/4/24 | D37: ='13-2-26'!I37 -> 1250000 | H37: =SUM(F37:G37) -> 0 | I37: =D37-F37 -> 1250000 | J37: =1/10*G37 -> 0
A38: 52 | B38: Siyo Dwiroso | C38: 16/4/24 | D38: ='13-2-26'!I38 -> 5800000 | H38: =SUM(F38:G38) -> 0 | I38: =D38-F38 -> 5800000 | J38: =1/10*G38 -> 0
A39: 60 | B39: Purwati | C39: 4/6/24 | D39: ='13-2-26'!I39 -> 14320000 | H39: =SUM(F39:G39) -> 0 | I39: =D39-F39 -> 14320000 | J39: =1/10*G39 -> 0
A40: 62 | B40: Tarsini | C40: 02/07/24 | D40: ='13-2-26'!I40 -> 200000 | H40: =SUM(F40:G40) -> 0 | I40: =D40-F40 -> 200000 | J40: =1/10*G40 -> 0
A41: 64 | B41: Santosa | C41: 09/07/24 | D41: ='13-2-26'!I41 -> 1800000 | H41: =SUM(F41:G41) -> 0 | I41: =D41-F41 -> 1800000 | J41: =1/10*G41 -> 0
A42: 65 | B42: Priyono | C42: 16/07/24 | D42: ='13-2-26'!I42 -> 1200000 | H42: =SUM(F42:G42) -> 0 | I42: =D42-F42 -> 1200000 | J42: =1/10*G42 -> 0
A43: 69 | B43: Karyono | C43: 30/07/24 | D43: ='13-2-26'!I43 -> 5250000 | H43: =SUM(F43:G43) -> 0 | I43: =D43-F43 -> 5250000 | J43: =1/10*G43 -> 0
A44: 70 | B44: Dwiyanto | C44: 06/08/24 | D44: ='13-2-26'!I44 -> 10320000 | H44: =SUM(F44:G44) -> 0 | I44: =D44-F44 -> 10320000 | J44: =1/10*G44 -> 0
A45: 71 | B45: Utami | C45: 20/08/24 | D45: ='13-2-26'!I45 -> 10875000 | H45: =SUM(F45:G45) -> 0 | I45: =D45-F45 -> 10875000 | J45: =1/10*G45 -> 0
A46: 73 | B46: Karjono | C46: 10/09/24 | D46: ='13-2-26'!I46 -> 450000 | H46: =SUM(F46:G46) -> 0 | I46: =D46-F46 -> 450000 | J46: =1/10*G46 -> 0
...

Sheet 24-2-26
A1: KOPERASI SERBA USAHA "CAHAYA DHAMMA PHALA"
A2: Badan Hukum No. 2/BH/XIV.1/II/2016 Tanggal 5 Februari 2016
A3: Dukuh Windusari, Desa Sokaraja, Kec. Pagentan, Kab. Banjarnegara 53455
A5: BUKU ANGSURAN PINJAMAN ANGGOTA
A6: Per 24 Februari 2026
A7: NO. | B7: NAMA | C7: TGL | E7: ANGSURAN PINJAMAN | I7: SISA | J7: SWK
E8: KE | F8: POKOK | G8: JASA | H8: JUMLAH
A9: 1 | B9: Suryadi | C9: 4-4-17 | D9: ='17-2-26'!I9 -> 5500000 | H9: =SUM(F9:G9) -> 0 | I9: =D9-F9 -> 5500000 | J9: =1/10*G9 -> 0
A10: 2 | B10: Waginah | C10: 16-5-17 | D10: ='17-2-26'!I10 -> 1910000 | H10: =SUM(F10:G10) -> 0 | I10: =D10-F10 -> 1910000 | J10: =1/10*G10 -> 0
A11: 3 | B11: Tarmono | C11: 18-8-20 | D11: ='17-2-26'!I11 -> 0 | H11: =SUM(F11:G11) -> 0 | I11: =D11-F11 -> 0 | J11: =1/10*G11 -> 0
A12: 4 | B12: Juliyah | C12: 2-2-21 | D12: ='17-2-26'!I12 -> 13750000 | H12: =SUM(F12:G12) -> 0 | I12: =D12-F12 -> 13750000 | J12: =1/10*G12 -> 0
A13: 5 | B13: Purwadi | C13: 14-03-21 | D13: ='17-2-26'!I13 -> 19950000 | H13: =SUM(F13:G13) -> 0 | I13: =D13-F13 -> 19950000 | J13: =1/10*G13 -> 0
A14: 6 | B14: Waluyo Ragil | C14: 27-04-21 | D14: ='17-2-26'!I14 -> 100000 | H14: =SUM(F14:G14) -> 0 | I14: =D14-F14 -> 100000 | J14: =1/10*G14 -> 0
A15: 7 | B15: Sapdono | C15: 24-8-23 | D15: ='17-2-26'!I15 -> 10500000 | H15: =SUM(F15:G15) -> 0 | I15: =D15-F15 -> 10500000 | J15: =1/10*G15 -> 0
A16: 8 | B16: Sudarma Widya | C16: 28-09-21 | D16: ='17-2-26'!I16 -> 15310000 | H16: =SUM(F16:G16) -> 0 | I16: =D16-F16 -> 15310000 | J16: =1/10*G16 -> 0
A17: 9 | B17: Rahmadi | C17: 15-2-22 | D17: ='17-2-26'!I17 -> 6150000 | H17: =SUM(F17:G17) -> 0 | I17: =D17-F17 -> 6150000 | J17: =1/10*G17 -> 0
A18: 10 | B18: Ratmi | C18: 8-3-22 | D18: ='17-2-26'!I18 -> 12595000 | E18: 11 | G18: 400000 | H18: =SUM(F18:G18) -> 400000 | I18: =D18-F18 -> 12595000 | J18: =1/10*G18 -> 40000
A19: 11 | B19: Cipret | C19: 21-6-22 | D19: ='17-2-26'!I19 -> 3750000 | H19: =SUM(F19:G19) -> 0 | I19: =D19-F19 -> 3750000 | J19: =1/10*G19 -> 0
A20: 12 | B20: Ika Kurniasih | C20: 03-1-22 | D20: ='17-2-26'!I20 -> 42000000 | H20: =SUM(F20:G20) -> 0 | I20: =D20-F20 -> 42000000 | J20: =1/10*G20 -> 0
A21: 13 | B21: Kamto | C21: 28-2-23 | D21: ='17-2-26'!I21 -> 12680000 | H21: =SUM(F21:G21) -> 0 | I21: =D21-F21 -> 12680000 | J21: =1/10*G21 -> 0
A22: 14 | B22: Handi Cahyono | C22: 04-04-23 | D22: ='17-2-26'!I22 -> 0 | H22: =SUM(F22:G22) -> 0 | I22: =D22-F22 -> 0 | J22: =1/10*G22 -> 0
A23: 15 | B23: Hartati | C23: 04-04-23 | D23: ='17-2-26'!I23 -> 1500000 | H23: =SUM(F23:G23) -> 0 | I23: =D23-F23 -> 1500000 | J23: =1/10*G23 -> 0
A24: 16 | B24: Sartiyah | C24: 04-04-23 | D24: ='17-2-26'!I24 -> 600000 | H24: =SUM(F24:G24) -> 0 | I24: =D24-F24 -> 600000 | J24: =1/10*G24 -> 0
A25: 17 | B25: Dwi Vijjayanti | C25: 11-04-23 | D25: ='17-2-26'!I25 -> 22200000 | H25: =SUM(F25:G25) -> 0 | I25: =D25-F25 -> 22200000 | J25: =1/10*G25 -> 0
A26: 18 | B26: Marsinem | C26: 2-5-23 | D26: ='17-2-26'!I26 -> 3800000 | H26: =SUM(F26:G26) -> 0 | I26: =D26-F26 -> 3800000 | J26: =1/10*G26 -> 0
A27: 19 | B27: Suharjanto | C27: 11/7/23 | D27: ='17-2-26'!I27 -> 760000 | H27: =SUM(F27:G27) -> 0 | I27: =D27-F27 -> 760000 | J27: =1/10*G27 -> 0
A28: 20 | B28: Saliyah | C28: 18/7/23 | D28: ='17-2-26'!I28 -> 0 | H28: =SUM(F28:G28) -> 0 | I28: =D28-F28 -> 0 | J28: =1/10*G28 -> 0
A29: 21 | B29: Suminah | C29: 26-9-23 | D29: ='17-2-26'!I29 -> 0 | H29: =SUM(F29:G29) -> 0 | I29: =D29-F29 -> 0 | J29: =1/10*G29 -> 0
A30: 22 | B30: Leni | C30: 10-10-23 | D30: ='17-2-26'!I30 -> 2750000 | H30: =SUM(F30:G30) -> 0 | I30: =D30-F30 -> 2750000 | J30: =1/10*G30 -> 0
... A33: 25 | B33: Kami | C33: 9/1/24 | D33: ='17-2-26'!I33 -> 600000 | H33: =SUM(F33:G33) -> 0 | I33: =D33-F33 -> 600000 | J33: =1/10*G33 -> 0
A34: 26 | B34: Wahyuni | C34: 30/1/24 | D34: ='17-2-26'!I34 -> 2800000 | E34: 14 | F34: 400000 | G34: 160000 | H34: =SUM(F34:G34) -> 560000 | I34: =D34-F34 -> 2400000 | J34: =1/10*G34 -> 16000
A35: 27 | B35: Karsih | C35: 30/1/24 | D35: ='17-2-26'!I35 -> 3500000 | H35: =SUM(F35:G35) -> 0 | I35: =D35-F35 -> 3500000 | J35: =1/10*G35 -> 0
A36: 28 | B36: Painten Darwito | C36: 16/2/24 | D36: ='17-2-26'!I36 -> 9200000 | H36: =SUM(F36:G36) -> 0 | I36: =D36-F36 -> 9200000 | J36: =1/10*G36 -> 0
A37: 29 | B37: Karni | C37: 2/4/24 | D37: ='17-2-26'!I37 -> 1250000 | H37: =SUM(F37:G37) -> 0 | I37: =D37-F37 -> 1250000 | J37: =1/10*G37 -> 0
A38: 30 | B38: Siyo Dwiroso | C38: 16/4/24 | D38: ='17-2-26'!I38 -> 5800000 | H38: =SUM(F38:G38) -> 0 | I38: =D38-F38 -> 5800000 | J38: =1/10*G38 -> 0
A39: 31 | B39: Purwati | C39: 4/6/24 | D39: ='17-2-26'!I39 -> 14320000 | H39: =SUM(F39:G39) -> 0 | I39: =D39-F39 -> 14320000 | J39: =1/10*G39 -> 0
A40: 32 | B40: Tarsini | C40: 02/07/24 | D40: ='17-2-26'!I40 -> 200000 | H40: =SUM(F40:G40) -> 0 | I40: =D40-F40 -> 200000 | J40: =1/10*G40 -> 0
A41: 33 | B41: Santosa | C41: 09/07/24 | D41: ='17-2-26'!I41 -> 1800000 | H41: =SUM(F41:G41) -> 0 | I41: =D41-F41 -> 1800000 | J41: =1/10*G41 -> 0
A42: 34 | B42: Priyono | C42: 16/07/24 | D42: ='17-2-26'!I42 -> 1200000 | H42: =SUM(F42:G42) -> 0 | I42: =D42-F42 -> 1200000 | J42: =1/10*G42 -> 0
A43: 35 | B43: Karyono | C43: 30/07/24 | D43: ='17-2-26'!I43 -> 5250000 | H43: =SUM(F43:G43) -> 0 | I43: =D43-F43 -> 5250000 | J43: =1/10*G43 -> 0
...

Sheet 4-3-26
A1: KOPERASI SERBA USAHA "CAHAYA DHAMMA PHALA"
A2: Badan Hukum No. 2/BH/XIV.1/II/2016 Tanggal 5 Februari 2016
A3: Dukuh Windusari, Desa Sokaraja, Kec. Pagentan, Kab. Banjarnegara 53455
A5: BUKU ANGSURAN PINJAMAN ANGGOTA
A6: Per 4 Maret 2026
A7: NO. | B7: NAMA | C7: TGL | E7: ANGSURAN PINJAMAN | I7: SISA | J7: SWK
E8: KE | F8: POKOK | G8: JASA | H8: JUMLAH
A9: 1 | B9: Suryadi | C9: 4-4-17 | D9: ='24-2-26'!I9 -> 5500000 | H9: =SUM(F9:G9) -> 0 | I9: =D9-F9 -> 5500000 | J9: =1/10*G9 -> 0
A10: 2 | B10: Waginah | C10: 16-5-17 | D10: ='24-2-26'!I10 -> 1910000 | H10: =SUM(F10:G10) -> 0 | I10: =D10-F10 -> 1910000 | J10: =1/10*G10 -> 0
A11: 3 | B11: Tarmono | C11: 18-8-20 | D11: ='24-2-26'!I11 -> 0 | H11: =SUM(F11:G11) -> 0 | I11: =D11-F11 -> 0 | J11: =1/10*G11 -> 0
A12: 4 | B12: Juliyah | C12: 2-2-21 | D12: ='24-2-26'!I12 -> 13750000 | H12: =SUM(F12:G12) -> 0 | I12: =D12-F12 -> 13750000 | J12: =1/10*G12 -> 0
A13: 5 | B13: Purwadi | C13: 14-03-21 | D13: ='24-2-26'!I13 -> 19950000 | H13: =SUM(F13:G13) -> 0 | I13: =D13-F13 -> 19950000 | J13: =1/10*G13 -> 0
A14: 6 | B14: Waluyo Ragil | C14: 27-04-21 | D14: ='24-2-26'!I14 -> 100000 | H14: =SUM(F14:G14) -> 0 | I14: =D14-F14 -> 100000 | J14: =1/10*G14 -> 0
A15: 7 | B15: Sapdono | C15: 24-8-23 | D15: ='24-2-26'!I15 -> 10500000 | H15: =SUM(F15:G15) -> 0 | I15: =D15-F15 -> 10500000 | J15: =1/10*G15 -> 0
A16: 8 | B16: Sudarma Widya | C16: 28-09-21 | D16: ='24-2-26'!I16 -> 15310000 | H16: =SUM(F16:G16) -> 0 | I16: =D16-F16 -> 15310000 | J16: =1/10*G16 -> 0
A17: 9 | B17: Rahmadi | C17: 15-2-22 | D17: ='24-2-26'!I17 -> 6150000 | H17: =SUM(F17:G17) -> 0 | I17: =D17-F17 -> 6150000 | J17: =1/10*G17 -> 0
A18: 10 | B18: Ratmi | C18: 8-3-22 | D18: ='24-2-26'!I18 -> 12595000 | H18: =SUM(F18:G18) -> 0 | I18: =D18-F18 -> 12595000 | J18: =1/10*G18 -> 0
A19: 11 | B19: Cipret | C19: 21-6-22 | D19: ='24-2-26'!I19 -> 3750000 | H19: =SUM(F19:G19) -> 0 | I19: =D19-F19 -> 3750000 | J19: =1/10*G19 -> 0
A20: 12 | B20: Ika Kurniasih | C20: 03-1-22 | D20: ='24-2-26'!I20 -> 42000000 | H20: =SUM(F20:G20) -> 0 | I20: =D20-F20 -> 42000000 | J20: =1/10*G20 -> 0
... A40: 32 | B40: Tarsini | C40: 02/07/24 | D40: ='24-2-26'!I40 -> 200000 | H40: =SUM(F40:G40) -> 0 | I40: =D40-F40 -> 200000 | J40: =1/10*G40 -> 0
A41: 33 | B41: Santosa | C41: 09/07/24 | D41: ='24-2-26'!I41 -> 1800000 | E41: 13 | F41: 300000 | G41: 120000 | H41: =SUM(F41:G41) -> 420000 | I41: =D41-F41 -> 1500000 | J41: =1/10*G41 -> 12000
A42: 34 | B42: Priyono | C42: 16/07/24 | D42: ='24-2-26'!I42 -> 1200000 | H42: =SUM(F42:G42) -> 0 | I42: =D42-F42 -> 1200000 | J42: =1/10*G42 -> 0
A43: 35 | B43: Karyono | C43: 30/07/24 | D43: ='24-2-26'!I43 -> 5250000 | H43: =SUM(F43:G43) -> 0 | I43: =D43-F43 -> 5250000 | J43: =1/10*G43 -> 0
A44: 36 | B44: Dwiyanto | C44: 06/08/24 | D44: ='24-2-26'!I44 -> 10320000 | H44: =SUM(F44:G44) -> 0 | I44: =D44-F44 -> 10320000 | J44: =1/10*G44 -> 0
A45: 37 | B45: Utami | C45: 20/08/24 | D45: ='24-2-26'!I45 -> 10875000 | H45: =SUM(F45:G45) -> 0 | I45: =D45-F45 -> 10875000 | J45: =1/10*G45 -> 0
A46: 38 | B46: Karjono | C46: 10/09/24 | D46: ='24-2-26'!I46 -> 450000 | H46: =SUM(F46:G46) -> 0 | I46: =D46-F46 -> 450000 | J46: =1/10*G46 -> 0
A47: 39 | B47: Kuswono Katam | C47: 05/11/24 | D47: ='24-2-26'!I47 -> 9600000 | H47: =SUM(F47:G47) -> 0 | I47: =D47-F47 -> 9600000 | J47: =1/10*G47 -> 0
A48: 40 | B48: Sarijem | C48: 05/11/24 | D48: ='24-2-26'!I48 -> 1000000 | H48: =SUM(F48:G48) -> 0 | I48: =D48-F48 -> 1000000 | J48: =1/10*G48 -> 0
A49: 41 | B49: Nisem | C49: 03/12/24 | D49: ='24-2-26'!I49 -> 9600000 | H49: =SUM(F49:G49) -> 0 | I49: =D49-F49 -> 9600000 | J49: =1/10*G49 -> 0
A50: 42 | B50: Saroji | C50: 17/12/24 | D50: ='24-2-26'!I50 -> 0 | H50: =SUM(F50:G50) -> 0 | I50: =D50-F50 -> 0 | J50: =1/10*G50 -> 0
A51: 43 | B51: Minardi | C51: 21/1/25 | D51: ='24-2-26'!I51 -> 15700000 | H51: =SUM(F51:G51) -> 0 | I51: =D51-F51 -> 15700000 | J51: =1/10*G51 -> 0
A52: 44 | B52: Kuat Siti Kirana | C52: 28/1/25 | D52: ='24-2-26'!I52 -> 25000000 | H52: =SUM(F52:G52) -> 0 | I52: =D52-F52 -> 25000000 | J52: =1/10*G52 -> 0
A53: 45 | B53: Vijja Ratano | C53: 18/2/25 | D53: ='24-2-26'!I53 -> 0 | H53: =SUM(F53:G53) -> 0 | I53: =D53-F53 -> 0 | J53: =1/10*G53 -> 0
... A72: 64 | B72: Vijja Ratano | C72: 24/2/26 | D72: ='24-2-26'!I72 -> 2000000 | H72: =SUM(F72:G72) -> 0 | I72: =D72-F72 -> 2000000 | J72: =1/10*G72 -> 0
A73: 65 | B73: Tukimin | C73: 24/2/26 | D73: 5000000 | H73: =SUM(F73:G73) -> 0 | I73: =D73-F73 -> 5000000 | J73: =1/10*G73 -> 0
A74: 66 | B74: Hartini | C74: 4/3/26 | D74: 4000000 | H74: =SUM(F74:G74) -> 0 | I74: =D74-F74 -> 4000000 | J74: =1/10*G74 -> 0
A75: 67 | B75: Suminah | C75: 4/3/26 | D75: 3000000 | H75: =SUM(F75:G75) -> 0 | I75: =D75-F75 -> 3000000 | J75: =1/10*G75 -> 0
D76: ='3-2-26'!I75 -> 0 | H76: =SUM(F76:G76) -> 0 | I76: =D76-F76 -> 0 | J76: =1/10*G76 -> 0
D77: ='3-2-26'!I76 -> 0 | H77: =SUM(F77:G77) -> 0 | I77: =D77-F77 -> 0 | J77: =1/10*G77 -> 0
D78: ='3-2-26'!I77 -> 0 | H78: =SUM(F78:G78) -> 0 | I78: =D78-F78 -> 0 | J78: =1/10*G78 -> 0
...

Sheet 10-3-26
A1: KOPERASI SERBA USAHA "CAHAYA DHAMMA PHALA"
A2: Badan Hukum No. 2/BH/XIV.1/II/2016 Tanggal 5 Februari 2016
A3: Dukuh Windusari, Desa Sokaraja, Kec. Pagentan, Kab. Banjarnegara 53455
A5: BUKU ANGSURAN PINJAMAN ANGGOTA
A6: Per 10 Maret 2026
A7: NO. | B7: NAMA | C7: TGL | E7: ANGSURAN PINJAMAN | I7: SISA | J7: SWK
E8: KE | F8: POKOK | G8: JASA | H8: JUMLAH
A9: 1 | B9: Suryadi | C9: 4-4-17 | D9: ='4-3-26'!I9 -> 5500000 | H9: =SUM(F9:G9) -> 0 | I9: =D9-F9 -> 5500000 | J9: =1/10*G9 -> 0
A10: 2 | B10: Waginah | C10: 16-5-17 | D10: ='4-3-26'!I10 -> 1910000 | H10: =SUM(F10:G10) -> 0 | I10: =D10-F10 -> 1910000 | J10: =1/10*G10 -> 0
A11: 3 | B11: Tarmono | C11: 18-8-20 | D11: ='4-3-26'!I11 -> 0 | H11: =SUM(F11:G11) -> 0 | I11: =D11-F11 -> 0 | J11: =1/10*G11 -> 0
A12: 4 | B12: Juliyah | C12: 2-2-21 | D12: ='4-3-26'!I12 -> 13750000 | H12: =SUM(F12:G12) -> 0 | I12: =D12-F12 -> 13750000 | J12: =1/10*G12 -> 0
A13: 5 | B13: Purwadi | C13: 14-03-21 | D13: ='4-3-26'!I13 -> 19950000 | H13: =SUM(F13:G13) -> 0 | I13: =D13-F13 -> 19950000 | J13: =1/10*G13 -> 0
A14: 6 | B14: Waluyo Ragil | C14: 27-04-21 | D14: ='4-3-26'!I14 -> 100000 | H14: =SUM(F14:G14) -> 0 | I14: =D14-F14 -> 100000 | J14: =1/10*G14 -> 0
A15: 7 | B15: Sapdono | C15: 24-8-23 | D15: ='4-3-26'!I15 -> 10500000 | H15: =SUM(F15:G15) -> 0 | I15: =D15-F15 -> 10500000 | J15: =1/10*G15 -> 0
A16: 8 | B16: Sudarma Widya | C16: 28-09-21 | D16: ='4-3-26'!I16 -> 15310000 | H16: =SUM(F16:G16) -> 0 | I16: =D16-F16 -> 15310000 | J16: =1/10*G16 -> 0
A17: 9 | B17: Rahmadi | C17: 15-2-22 | D17: ='4-3-26'!I17 -> 6150000 | H17: =SUM(F17:G17) -> 0 | I17: =D17-F17 -> 6150000 | J17: =1/10*G17 -> 0
A18: 10 | B18: Ratmi | C18: 8-3-22 | D18: ='4-3-26'!I18 -> 12595000 | H18: =SUM(F18:G18) -> 0 | I18: =D18-F18 -> 12595000 | J18: =1/10*G18 -> 0
A19: 11 | B19: Cipret | C19: 21-6-22 | D19: ='4-3-26'!I19 -> 3750000 | H19: =SUM(F19:G19) -> 0 | I19: =D19-F19 -> 3750000 | J19: =1/10*G19 -> 0
A20: 12 | B20: Ika Kurniasih | C20: 03-1-22 | D20: ='4-3-26'!I20 -> 42000000 | H20: =SUM(F20:G20) -> 0 | I20: =D20-F20 -> 42000000 | J20: =1/10*G20 -> 0
... A39: 31 | B39: Purwati | C39: 4/6/24 | D39: ='4-3-26'!I39 -> 14320000 | H39: =SUM(F39:G39) -> 0 | I39: =D39-F39 -> 14320000 | J39: =1/10*G39 -> 0
A40: 32 | B40: Tarsini | C40: 02/07/24 | D40: ='4-3-26'!I40 -> 200000 | E40: 15 | F40: 200000 | G40: 60000 | H40: =SUM(F40:G40) -> 260000 | I40: =D40-F40 -> 0 | J40: =1/10*G40 -> 6000
A41: 33 | B41: Santosa | C41: 09/07/24 | D41: ='4-3-26'!I41 -> 1500000 | H41: =SUM(F41:G41) -> 0 | I41: =D41-F41 -> 1500000 | J41: =1/10*G41 -> 0
A42: 34 | B42: Priyono | C42: 16/07/24 | D42: ='4-3-26'!I42 -> 1200000 | H42: =SUM(F42:G42) -> 0 | I42: =D42-F42 -> 1200000 | J42: =1/10*G42 -> 0
A43: 35 | B43: Karyono | C43: 30/07/24 | D43: ='4-3-26'!I43 -> 5250000 | H43: =SUM(F43:G43) -> 0 | I43: =D43-F43 -> 5250000 | J43: =1/10*G43 -> 0
A44: 36 | B44: Dwiyanto | C44: 06/08/24 | D44: ='4-3-26'!I44 -> 10320000 | H44: =SUM(F44:G44) -> 0 | I44: =D44-F44 -> 10320000 | J44: =1/10*G44 -> 0
A45: 37 | B45: Utami | C45: 20/08/24 | D45: ='4-3-26'!I45 -> 10875000 | H45: =SUM(F45:G45) -> 0 | I45: =D45-F45 -> 10875000 | J45: =1/10*G45 -> 0
A46: 38 | B46: Karjono | C46: 10/09/24 | D46: ='4-3-26'!I46 -> 450000 | H46: =SUM(F46:G46) -> 0 | I46: =D46-F46 -> 450000 | J46: =1/10*G46 -> 0
A47: 39 | B47: Kuswono Katam | C47: 05/11/24 | D47: ='4-3-26'!I47 -> 9600000 | E47: 9 | F47: 300000 | G47: 240000 | H47: =SUM(F47:G47) -> 540000 | I47: =D47-F47 -> 9300000 | J47: =1/10*G47 -> 24000
A48: 40 | B48: Sarijem | C48: 05/11/24 | D48: ='4-3-26'!I48 -> 1000000 | H48: =SUM(F48:G48) -> 0 | I48: =D48-F48 -> 1000000 | J48: =1/10*G48 -> 0
A49: 41 | B49: Nisem | C49: 03/12/24 | D49: ='4-3-26'!I49 -> 9600000 | H49: =SUM(F49:G49) -> 0 | I49: =D49-F49 -> 9600000 | J49: =1/10*G49 -> 0
A50: 42 | B50: Saroji | C50: 17/12/24 | D50: ='4-3-26'!I50 -> 0 | H50: =SUM(F50:G50) -> 0 | I50: =D50-F50 -> 0 | J50: =1/10*G50 -> 0
A51: 43 | B51: Minardi | C51: 21/1/25 | D51: ='4-3-26'!I51 -> 15700000 | H51: =SUM(F51:G51) -> 0 | I51: =D51-F51 -> 15700000 | J51: =1/10*G51 -> 0
A52: 44 | B52: Kuat Siti Kirana | C52: 28/1/25 | D52: ='4-3-26'!I52 -> 25000000 | H52: =SUM(F52:G52) -> 0 | I52: =D52-F52 -> 25000000 | J52: =1/10*G52 -> 0
A53: 45 | B53: Vijja Ratano | C53: 18/2/25 | D53: ='4-3-26'!I53 -> 0 | H53: =SUM(F53:G53) -> 0 | I53: =D53-F53 -> 0 | J53: =1/10*G53 -> 0
A54: 46 | B54: Suroto | C54: 18/2/25 | D54: ='4-3-26'!I54 -> 4800000 | H54: =SUM(F54:G54) -> 0 | I54: =D54-F54 -> 4800000 | J54: =1/10*G54 -> 0
A55: 47 | B55: Sono | C55: 25/2/25 | D55: ='4-3-26'!I55 -> 7460000 | H55: =SUM(F55:G55) -> 0 | I55: =D55-F55 -> 7460000 | J55: =1/10*G55 -> 0
A56: 48 | B56: Metta Candra D. | C56: 25/2/25 | D56: ='4-3-26'!I56 -> 400000 | H56: =SUM(F56:G56) -> 0 | I56: =D56-F56 -> 400000 | J56: =1/10*G56 -> 0
A57: 49 | B57: Mislam | C57: 25/2/25 | D57: ='4-3-26'!I57 -> 20000000 | H57: =SUM(F57:G57) -> 0 | I57: =D57-F57 -> 20000000 | J57: =1/10*G57 -> 0
A58: 50 | B58: Lewih | C58: 25/3/25 | D58: ='4-3-26'!I58 -> 1315000 | H58: =SUM(F58:G58) -> 0 | I58: =D58-F58 -> 1315000 | J58: =1/10*G58 -> 0
A59: 51 | B59: Rusmini Bolot | C59: 8/4/25 | D59: ='4-3-26'!I59 -> 0 | H59: =SUM(F59:G59) -> 0 | I59: =D59-F59 -> 0 | J59: =1/10*G59 -> 0
...

Sheet 17-3-26
A1: KOPERASI SERBA USAHA "CAHAYA DHAMMA PHALA"
A2: Badan Hukum No. 2/BH/XIV.1/II/2016 Tanggal 5 Februari 2016
A3: Dukuh Windusari, Desa Sokaraja, Kec. Pagentan, Kab. Banjarnegara 53455
A5: BUKU ANGSURAN PINJAMAN ANGGOTA
A6: Per 17 Maret 2026
A7: NO. | B7: NAMA | C7: TGL | E7: ANGSURAN PINJAMAN | I7: SISA | J7: SWK
E8: KE | F8: POKOK | G8: JASA | H8: JUMLAH
A9: 1 | B9: Suryadi | C9: 4-4-17 | D9: ='10-3-26'!I9 -> 5500000 | H9: =SUM(F9:G9) -> 0 | I9: =D9-F9 -> 5500000 | J9: =1/10*G9 -> 0
A10: 2 | B10: Waginah | C10: 16-5-17 | D10: ='10-3-26'!I10 -> 1910000 | H10: =SUM(F10:G10) -> 0 | I10: =D10-F10 -> 1910000 | J10: =1/10*G10 -> 0
A11: 3 | B11: Tarmono | C11: 18-8-20 | D11: ='10-3-26'!I11 -> 0 | H11: =SUM(F11:G11) -> 0 | I11: =D11-F11 -> 0 | J11: =1/10*G11 -> 0
A12: 4 | B12: Juliyah | C12: 2-2-21 | D12: ='10-3-26'!I12 -> 13750000 | H12: =SUM(F12:G12) -> 0 | I12: =D12-F12 -> 13750000 | J12: =1/10*G12 -> 0
A13: 5 | B13: Purwadi | C13: 14-03-21 | D13: ='10-3-26'!I13 -> 19950000 | H13: =SUM(F13:G13) -> 0 | I13: =D13-F13 -> 19950000 | J13: =1/10*G13 -> 0
A14: 6 | B14: Waluyo Ragil | C14: 27-04-21 | D14: ='10-3-26'!I14 -> 100000 | H14: =SUM(F14:G14) -> 0 | I14: =D14-F14 -> 100000 | J14: =1/10*G14 -> 0
A15: 7 | B15: Sapdono | C15: 24-8-23 | D15: ='10-3-26'!I15 -> 10500000 | H15: =SUM(F15:G15) -> 0 | I15: =D15-F15 -> 10500000 | J15: =1/10*G15 -> 0
A16: 8 | B16: Sudarma Widya | C16: 28-09-21 | D16: ='10-3-26'!I16 -> 15310000 | H16: =SUM(F16:G16) -> 0 | I16: =D16-F16 -> 15310000 | J16: =1/10*G16 -> 0
A17: 9 | B17: Rahmadi | C17: 15-2-22 | D17: ='10-3-26'!I17 -> 6150000 | H17: =SUM(F17:G17) -> 0 | I17: =D17-F17 -> 6150000 | J17: =1/10*G17 -> 0
A18: 10 | B18: Ratmi | C18: 8-3-22 | D18: ='10-3-26'!I18 -> 12595000 | H18: =SUM(F18:G18) -> 0 | I18: =D18-F18 -> 12595000 | J18: =1/10*G18 -> 0
A19: 11 | B19: Cipret | C19: 21-6-22 | D19: ='10-3-26'!I19 -> 3750000 | H19: =SUM(F19:G19) -> 0 | I19: =D19-F19 -> 3750000 | J19: =1/10*G19 -> 0
A20: 12 | B20: Ika Kurniasih | C20: 03-1-22 | D20: ='10-3-26'!I20 -> 42000000 | H20: =SUM(F20:G20) -> 0 | I20: =D20-F20 -> 42000000 | J20: =1/10*G20 -> 0
... A45: 37 | B45: Utami | C45: 20/08/24 | D45: ='10-3-26'!I45 -> 10875000 | H45: =SUM(F45:G45) -> 0 | I45: =D45-F45 -> 10875000 | J45: =1/10*G45 -> 0
A46: 38 | B46: Karjono | C46: 10/09/24 | D46: ='10-3-26'!I46 -> 450000 | E46: 18 | F46: 150000 | G46: 60000 | H46: =SUM(F46:G46) -> 210000 | I46: =D46-F46 -> 300000 | J46: =1/10*G46 -> 6000
A47: 39 | B47: Kuswono Katam | C47: 05/11/24 | D47: ='10-3-26'!I47 -> 9300000 | H47: =SUM(F47:G47) -> 0 | I47: =D47-F47 -> 9300000 | J47: =1/10*G47 -> 0
A48: 40 | B48: Sarijem | C48: 05/11/24 | D48: ='10-3-26'!I48 -> 1000000 | H48: =SUM(F48:G48) -> 0 | I48: =D48-F48 -> 1000000 | J48: =1/10*G48 -> 0
A49: 41 | B49: Nisem | C49: 03/12/24 | D49: ='10-3-26'!I49 -> 9600000 | H49: =SUM(F49:G49) -> 0 | I49: =D49-F49 -> 9600000 | J49: =1/10*G49 -> 0
A50: 42 | B50: Saroji | C50: 17/12/24 | D50: ='10-3-26'!I50 -> 0 | H50: =SUM(F50:G50) -> 0 | I50: =D50-F50 -> 0 | J50: =1/10*G50 -> 0
A51: 43 | B51: Minardi | C51: 21/1/25 | D51: ='10-3-26'!I51 -> 15700000 | H51: =SUM(F51:G51) -> 0 | I51: =D51-F51 -> 15700000 | J51: =1/10*G51 -> 0
A52: 44 | B52: Kuat Siti Kirana | C52: 28/1/25 | D52: ='10-3-26'!I52 -> 25000000 | H52: =SUM(F52:G52) -> 0 | I52: =D52-F52 -> 25000000 | J52: =1/10*G52 -> 0
A53: 45 | B53: Vijja Ratano | C53: 18/2/25 | D53: ='10-3-26'!I53 -> 0 | H53: =SUM(F53:G53) -> 0 | I53: =D53-F53 -> 0 | J53: =1/10*G53 -> 0
A54: 46 | B54: Suroto | C54: 18/2/25 | D54: ='10-3-26'!I54 -> 4800000 | H54: =SUM(F54:G54) -> 0 | I54: =D54-F54 -> 4800000 | J54: =1/10*G54 -> 0
A55: 47 | B55: Sono | C55: 25/2/25 | D55: ='10-3-26'!I55 -> 7460000 | H55: =SUM(F55:G55) -> 0 | I55: =D55-F55 -> 7460000 | J55: =1/10*G55 -> 0
